# Goxel 0.11.0
# One line per voxel
# X Y Z RRGGBB
14 12 0 306082
15 12 0 ffffff
13 13 0 ffffff
14 13 0 ffffff
15 13 0 ffffff
12 14 0 306082
13 14 0 306082
14 14 0 ffffff
15 14 0 ffffff
12 15 0 306082
13 15 0 ffffff
14 15 0 ffffff
15 15 0 ffffff
14 9 1 306082
15 9 1 306082
12 10 1 306082
13 10 1 306082
14 10 1 306082
15 10 1 ffffff
11 11 1 306082
12 11 1 306082
13 11 1 306082
14 11 1 306082
15 11 1 ffffff
10 12 1 ffffff
11 12 1 ffffff
12 12 1 ffffff
13 12 1 306082
14 12 1 306082
15 12 1 ffffff
10 13 1 ffffff
11 13 1 ffffff
12 13 1 ffffff
13 13 1 306082
14 13 1 306082
15 13 1 ffffff
9 14 1 306082
10 14 1 306082
11 14 1 306082
12 14 1 306082
13 14 1 306082
14 14 1 306082
15 14 1 306082
9 15 1 306082
10 15 1 306082
11 15 1 306082
12 15 1 306082
13 15 1 306082
14 15 1 ffffff
15 15 1 ffffff
15 7 2 306082
12 8 2 306082
13 8 2 306082
14 8 2 306082
15 8 2 306082
10 9 2 306082
11 9 2 306082
12 9 2 306082
13 9 2 306082
14 9 2 306082
15 9 2 306082
9 10 2 306082
10 10 2 306082
11 10 2 306082
12 10 2 306082
13 10 2 306082
14 10 2 306082
15 10 2 306082
9 11 2 ffffff
10 11 2 ffffff
11 11 2 306082
12 11 2 306082
13 11 2 306082
14 11 2 306082
15 11 2 306082
8 12 2 306082
9 12 2 ffffff
10 12 2 ffffff
11 12 2 ffffff
12 12 2 306082
13 12 2 306082
14 12 2 306082
15 12 2 306082
8 13 2 306082
9 13 2 306082
10 13 2 ffffff
11 13 2 306082
12 13 2 306082
13 13 2 306082
14 13 2 306082
15 13 2 306082
8 14 2 306082
9 14 2 306082
10 14 2 306082
11 14 2 306082
12 14 2 306082
13 14 2 306082
14 14 2 306082
15 14 2 ffffff
7 15 2 306082
8 15 2 306082
9 15 2 306082
10 15 2 306082
11 15 2 306082
12 15 2 ffffff
13 15 2 ffffff
14 15 2 ffffff
15 15 2 ffffff
13 6 3 306082
14 6 3 306082
15 6 3 306082
11 7 3 99e550
12 7 3 99e550
13 7 3 306082
14 7 3 306082
15 7 3 306082
9 8 3 306082
10 8 3 99e550
11 8 3 99e550
12 8 3 306082
13 8 3 306082
14 8 3 306082
15 8 3 306082
8 9 3 306082
9 9 3 306082
10 9 3 306082
11 9 3 306082
12 9 3 306082
13 9 3 306082
14 9 3 306082
15 9 3 306082
8 10 3 306082
9 10 3 306082
10 10 3 306082
11 10 3 306082
12 10 3 306082
13 10 3 306082
14 10 3 306082
15 10 3 306082
7 11 3 306082
8 11 3 306082
9 11 3 306082
10 11 3 306082
11 11 3 306082
12 11 3 306082
13 11 3 306082
14 11 3 306082
15 11 3 306082
7 12 3 306082
8 12 3 306082
9 12 3 306082
10 12 3 306082
11 12 3 306082
12 12 3 306082
13 12 3 306082
14 12 3 306082
15 12 3 306082
6 13 3 306082
7 13 3 306082
8 13 3 306082
9 13 3 306082
10 13 3 306082
11 13 3 306082
12 13 3 306082
13 13 3 306082
14 13 3 306082
15 13 3 306082
6 14 3 306082
7 14 3 306082
8 14 3 306082
9 14 3 306082
10 14 3 306082
11 14 3 306082
12 14 3 306082
13 14 3 306082
14 14 3 306082
15 14 3 ffffff
6 15 3 306082
7 15 3 306082
8 15 3 306082
9 15 3 306082
10 15 3 306082
11 15 3 306082
12 15 3 ffffff
13 15 3 ffffff
14 15 3 ffffff
15 15 3 ffffff
12 5 4 99e550
13 5 4 306082
14 5 4 306082
15 5 4 306082
10 6 4 306082
11 6 4 306082
12 6 4 99e550
13 6 4 306082
14 6 4 306082
15 6 4 306082
9 7 4 306082
10 7 4 306082
11 7 4 306082
12 7 4 99e550
13 7 4 306082
14 7 4 306082
15 7 4 306082
8 8 4 306082
9 8 4 306082
10 8 4 306082
11 8 4 306082
12 8 4 306082
13 8 4 306082
14 8 4 306082
15 8 4 306082
7 9 4 306082
8 9 4 306082
9 9 4 306082
10 9 4 306082
11 9 4 306082
12 9 4 306082
13 9 4 306082
14 9 4 306082
15 9 4 306082
6 10 4 306082
7 10 4 306082
8 10 4 306082
9 10 4 306082
10 10 4 306082
11 10 4 306082
12 10 4 306082
13 10 4 306082
14 10 4 306082
15 10 4 306082
6 11 4 306082
7 11 4 306082
8 11 4 306082
9 11 4 306082
10 11 4 306082
11 11 4 306082
12 11 4 306082
13 11 4 306082
14 11 4 306082
15 11 4 306082
5 12 4 306082
6 12 4 306082
7 12 4 306082
8 12 4 306082
9 12 4 306082
10 12 4 306082
11 12 4 306082
12 12 4 306082
13 12 4 306082
14 12 4 306082
15 12 4 306082
5 13 4 306082
6 13 4 306082
7 13 4 306082
8 13 4 306082
9 13 4 306082
10 13 4 306082
11 13 4 306082
12 13 4 306082
13 13 4 306082
14 13 4 306082
15 13 4 306082
5 14 4 306082
6 14 4 306082
7 14 4 306082
8 14 4 306082
9 14 4 306082
10 14 4 306082
11 14 4 306082
12 14 4 306082
13 14 4 306082
14 14 4 306082
15 14 4 306082
5 15 4 306082
6 15 4 306082
7 15 4 306082
8 15 4 306082
9 15 4 306082
10 15 4 306082
11 15 4 306082
12 15 4 306082
13 15 4 306082
14 15 4 306082
15 15 4 ffffff
12 4 5 99e550
13 4 5 306082
14 4 5 306082
15 4 5 306082
10 5 5 99e550
11 5 5 99e550
12 5 5 99e550
13 5 5 306082
14 5 5 306082
15 5 5 306082
9 6 5 306082
10 6 5 99e550
11 6 5 99e550
12 6 5 306082
13 6 5 306082
14 6 5 306082
15 6 5 306082
7 7 5 306082
8 7 5 306082
9 7 5 306082
10 7 5 306082
11 7 5 306082
12 7 5 306082
13 7 5 306082
14 7 5 306082
15 7 5 306082
7 8 5 306082
8 8 5 306082
9 8 5 306082
10 8 5 306082
11 8 5 306082
12 8 5 306082
13 8 5 306082
14 8 5 306082
15 8 5 306082
6 9 5 306082
7 9 5 306082
8 9 5 306082
9 9 5 306082
10 9 5 306082
11 9 5 306082
12 9 5 306082
13 9 5 306082
14 9 5 306082
15 9 5 306082
5 10 5 306082
6 10 5 306082
7 10 5 306082
8 10 5 306082
9 10 5 306082
10 10 5 306082
11 10 5 306082
12 10 5 306082
13 10 5 306082
14 10 5 306082
15 10 5 306082
5 11 5 306082
6 11 5 306082
7 11 5 306082
8 11 5 306082
9 11 5 306082
10 11 5 306082
11 11 5 306082
12 11 5 306082
13 11 5 306082
14 11 5 306082
15 11 5 306082
4 12 5 306082
5 12 5 306082
6 12 5 306082
7 12 5 306082
8 12 5 306082
9 12 5 306082
10 12 5 306082
11 12 5 306082
12 12 5 306082
13 12 5 306082
14 12 5 306082
15 12 5 306082
4 13 5 306082
5 13 5 306082
6 13 5 306082
7 13 5 306082
8 13 5 306082
9 13 5 306082
10 13 5 306082
11 13 5 306082
12 13 5 306082
13 13 5 306082
14 13 5 306082
15 13 5 306082
4 14 5 306082
5 14 5 306082
6 14 5 306082
7 14 5 306082
8 14 5 306082
9 14 5 306082
10 14 5 306082
11 14 5 306082
12 14 5 306082
13 14 5 306082
14 14 5 306082
15 14 5 306082
4 15 5 306082
5 15 5 306082
6 15 5 306082
7 15 5 306082
8 15 5 306082
9 15 5 306082
10 15 5 306082
11 15 5 306082
12 15 5 306082
13 15 5 306082
14 15 5 306082
15 15 5 306082
13 3 6 306082
14 3 6 306082
15 3 6 306082
10 4 6 99e550
11 4 6 99e550
12 4 6 99e550
13 4 6 306082
14 4 6 306082
15 4 6 306082
9 5 6 306082
10 5 6 99e550
11 5 6 99e550
12 5 6 99e550
13 5 6 306082
14 5 6 306082
15 5 6 306082
7 6 6 306082
8 6 6 306082
9 6 6 306082
10 6 6 99e550
11 6 6 99e550
12 6 6 306082
13 6 6 306082
14 6 6 306082
15 6 6 306082
6 7 6 306082
7 7 6 306082
8 7 6 306082
9 7 6 306082
10 7 6 306082
11 7 6 306082
12 7 6 306082
13 7 6 306082
14 7 6 306082
15 7 6 306082
6 8 6 306082
7 8 6 306082
8 8 6 306082
9 8 6 306082
10 8 6 306082
11 8 6 306082
12 8 6 306082
13 8 6 306082
14 8 6 306082
15 8 6 306082
5 9 6 306082
6 9 6 306082
7 9 6 306082
8 9 6 306082
9 9 6 306082
10 9 6 306082
11 9 6 306082
12 9 6 306082
13 9 6 306082
14 9 6 306082
15 9 6 306082
4 10 6 306082
5 10 6 306082
6 10 6 306082
7 10 6 306082
8 10 6 306082
9 10 6 306082
10 10 6 306082
11 10 6 306082
12 10 6 306082
13 10 6 306082
14 10 6 306082
15 10 6 306082
4 11 6 306082
5 11 6 306082
6 11 6 306082
7 11 6 306082
8 11 6 306082
9 11 6 306082
10 11 6 306082
11 11 6 306082
12 11 6 306082
13 11 6 306082
14 11 6 306082
15 11 6 306082
4 12 6 306082
5 12 6 306082
6 12 6 306082
7 12 6 306082
8 12 6 306082
9 12 6 306082
10 12 6 306082
11 12 6 306082
12 12 6 306082
13 12 6 306082
14 12 6 306082
15 12 6 306082
3 13 6 306082
4 13 6 306082
5 13 6 306082
6 13 6 306082
7 13 6 306082
8 13 6 306082
9 13 6 306082
10 13 6 306082
11 13 6 306082
12 13 6 306082
13 13 6 306082
14 13 6 306082
15 13 6 306082
3 14 6 306082
4 14 6 306082
5 14 6 306082
6 14 6 306082
7 14 6 306082
8 14 6 306082
9 14 6 306082
10 14 6 306082
11 14 6 306082
12 14 6 306082
13 14 6 306082
14 14 6 306082
15 14 6 306082
3 15 6 306082
4 15 6 306082
5 15 6 306082
6 15 6 306082
7 15 6 306082
8 15 6 306082
9 15 6 306082
10 15 6 306082
11 15 6 306082
12 15 6 306082
13 15 6 306082
14 15 6 306082
15 15 6 306082
15 2 7 306082
11 3 7 99e550
12 3 7 99e550
13 3 7 306082
14 3 7 306082
15 3 7 306082
9 4 7 306082
10 4 7 99e550
11 4 7 99e550
12 4 7 306082
13 4 7 306082
14 4 7 306082
15 4 7 306082
7 5 7 306082
8 5 7 306082
9 5 7 306082
10 5 7 99e550
11 5 7 99e550
12 5 7 306082
13 5 7 306082
14 5 7 306082
15 5 7 306082
6 6 7 306082
7 6 7 306082
8 6 7 306082
9 6 7 306082
10 6 7 306082
11 6 7 306082
12 6 7 306082
13 6 7 306082
14 6 7 306082
15 6 7 306082
5 7 7 306082
6 7 7 306082
7 7 7 306082
8 7 7 306082
9 7 7 306082
10 7 7 306082
11 7 7 306082
12 7 7 306082
13 7 7 306082
14 7 7 306082
15 7 7 306082
5 8 7 306082
6 8 7 306082
7 8 7 306082
8 8 7 306082
9 8 7 306082
10 8 7 306082
11 8 7 306082
12 8 7 306082
13 8 7 306082
14 8 7 306082
15 8 7 306082
4 9 7 306082
5 9 7 306082
6 9 7 306082
7 9 7 306082
8 9 7 306082
9 9 7 306082
10 9 7 306082
11 9 7 306082
12 9 7 306082
13 9 7 306082
14 9 7 306082
15 9 7 306082
4 10 7 306082
5 10 7 306082
6 10 7 306082
7 10 7 306082
8 10 7 306082
9 10 7 306082
10 10 7 306082
11 10 7 306082
12 10 7 306082
13 10 7 306082
14 10 7 306082
15 10 7 306082
3 11 7 306082
4 11 7 306082
5 11 7 306082
6 11 7 306082
7 11 7 306082
8 11 7 306082
9 11 7 306082
10 11 7 306082
11 11 7 306082
12 11 7 306082
13 11 7 306082
14 11 7 306082
15 11 7 306082
3 12 7 306082
4 12 7 306082
5 12 7 306082
6 12 7 306082
7 12 7 306082
8 12 7 306082
9 12 7 306082
10 12 7 306082
11 12 7 306082
12 12 7 306082
13 12 7 306082
14 12 7 306082
15 12 7 306082
3 13 7 306082
4 13 7 306082
5 13 7 306082
6 13 7 306082
7 13 7 306082
8 13 7 306082
9 13 7 306082
10 13 7 306082
11 13 7 306082
12 13 7 306082
13 13 7 306082
14 13 7 306082
15 13 7 306082
3 14 7 306082
4 14 7 306082
5 14 7 306082
6 14 7 306082
7 14 7 306082
8 14 7 306082
9 14 7 306082
10 14 7 306082
11 14 7 306082
12 14 7 306082
13 14 7 306082
14 14 7 306082
15 14 7 306082
2 15 7 306082
3 15 7 306082
4 15 7 306082
5 15 7 306082
6 15 7 306082
7 15 7 306082
8 15 7 306082
9 15 7 306082
10 15 7 306082
11 15 7 306082
12 15 7 306082
13 15 7 306082
14 15 7 306082
15 15 7 306082
12 2 8 306082
13 2 8 306082
14 2 8 306082
15 2 8 306082
9 3 8 306082
10 3 8 99e550
11 3 8 99e550
12 3 8 99e550
13 3 8 306082
14 3 8 306082
15 3 8 306082
8 4 8 306082
9 4 8 306082
10 4 8 306082
11 4 8 306082
12 4 8 306082
13 4 8 306082
14 4 8 306082
15 4 8 306082
7 5 8 99e550
8 5 8 306082
9 5 8 306082
10 5 8 306082
11 5 8 306082
12 5 8 306082
13 5 8 306082
14 5 8 306082
15 5 8 306082
6 6 8 99e550
7 6 8 99e550
8 6 8 306082
9 6 8 306082
10 6 8 306082
11 6 8 306082
12 6 8 306082
13 6 8 306082
14 6 8 306082
15 6 8 306082
5 7 8 99e550
6 7 8 99e550
7 7 8 306082
8 7 8 306082
9 7 8 306082
10 7 8 306082
11 7 8 306082
12 7 8 306082
13 7 8 306082
14 7 8 306082
15 7 8 306082
4 8 8 306082
5 8 8 306082
6 8 8 306082
7 8 8 306082
8 8 8 306082
9 8 8 306082
10 8 8 306082
11 8 8 306082
12 8 8 306082
13 8 8 306082
14 8 8 306082
15 8 8 306082
3 9 8 306082
4 9 8 306082
5 9 8 306082
6 9 8 306082
7 9 8 306082
8 9 8 306082
9 9 8 306082
10 9 8 306082
11 9 8 306082
12 9 8 306082
13 9 8 306082
14 9 8 306082
15 9 8 306082
3 10 8 306082
4 10 8 306082
5 10 8 306082
6 10 8 306082
7 10 8 306082
8 10 8 306082
9 10 8 306082
10 10 8 306082
11 10 8 306082
12 10 8 306082
13 10 8 306082
14 10 8 306082
15 10 8 306082
3 11 8 306082
4 11 8 306082
5 11 8 306082
6 11 8 306082
7 11 8 306082
8 11 8 306082
9 11 8 306082
10 11 8 306082
11 11 8 306082
12 11 8 306082
13 11 8 306082
14 11 8 306082
15 11 8 306082
2 12 8 306082
3 12 8 306082
4 12 8 306082
5 12 8 306082
6 12 8 306082
7 12 8 306082
8 12 8 306082
9 12 8 306082
10 12 8 306082
11 12 8 306082
12 12 8 306082
13 12 8 306082
14 12 8 306082
15 12 8 306082
2 13 8 306082
3 13 8 306082
4 13 8 306082
5 13 8 306082
6 13 8 306082
7 13 8 306082
8 13 8 306082
9 13 8 306082
10 13 8 306082
11 13 8 306082
12 13 8 306082
13 13 8 306082
14 13 8 306082
15 13 8 306082
2 14 8 306082
3 14 8 306082
4 14 8 306082
5 14 8 306082
6 14 8 306082
7 14 8 306082
8 14 8 306082
9 14 8 306082
10 14 8 306082
11 14 8 306082
12 14 8 306082
13 14 8 306082
14 14 8 306082
15 14 8 306082
2 15 8 306082
3 15 8 306082
4 15 8 306082
5 15 8 306082
6 15 8 306082
7 15 8 306082
8 15 8 306082
9 15 8 306082
10 15 8 306082
11 15 8 306082
12 15 8 306082
13 15 8 306082
14 15 8 306082
15 15 8 306082
14 1 9 306082
15 1 9 306082
10 2 9 99e550
11 2 9 306082
12 2 9 306082
13 2 9 306082
14 2 9 306082
15 2 9 306082
8 3 9 306082
9 3 9 306082
10 3 9 99e550
11 3 9 306082
12 3 9 306082
13 3 9 306082
14 3 9 306082
15 3 9 306082
7 4 9 99e550
8 4 9 99e550
9 4 9 306082
10 4 9 306082
11 4 9 306082
12 4 9 306082
13 4 9 306082
14 4 9 306082
15 4 9 306082
6 5 9 99e550
7 5 9 99e550
8 5 9 99e550
9 5 9 99e550
10 5 9 306082
11 5 9 306082
12 5 9 306082
13 5 9 306082
14 5 9 306082
15 5 9 306082
5 6 9 99e550
6 6 9 99e550
7 6 9 99e550
8 6 9 99e550
9 6 9 99e550
10 6 9 306082
11 6 9 306082
12 6 9 306082
13 6 9 306082
14 6 9 306082
15 6 9 306082
4 7 9 99e550
5 7 9 99e550
6 7 9 99e550
7 7 9 99e550
8 7 9 99e550
9 7 9 306082
10 7 9 306082
11 7 9 306082
12 7 9 306082
13 7 9 306082
14 7 9 306082
15 7 9 306082
3 8 9 306082
4 8 9 99e550
5 8 9 99e550
6 8 9 99e550
7 8 9 99e550
8 8 9 306082
9 8 9 306082
10 8 9 306082
11 8 9 306082
12 8 9 306082
13 8 9 306082
14 8 9 306082
15 8 9 306082
3 9 9 306082
4 9 9 306082
5 9 9 306082
6 9 9 306082
7 9 9 306082
8 9 9 306082
9 9 9 306082
10 9 9 306082
11 9 9 306082
12 9 9 306082
13 9 9 306082
14 9 9 306082
15 9 9 306082
2 10 9 306082
3 10 9 306082
4 10 9 306082
5 10 9 306082
6 10 9 306082
7 10 9 306082
8 10 9 306082
9 10 9 306082
10 10 9 306082
11 10 9 306082
12 10 9 306082
13 10 9 306082
14 10 9 306082
15 10 9 306082
2 11 9 306082
3 11 9 306082
4 11 9 306082
5 11 9 306082
6 11 9 306082
7 11 9 306082
8 11 9 306082
9 11 9 306082
10 11 9 306082
11 11 9 306082
12 11 9 306082
13 11 9 306082
14 11 9 306082
15 11 9 306082
2 12 9 306082
3 12 9 306082
4 12 9 306082
5 12 9 306082
6 12 9 306082
7 12 9 306082
8 12 9 306082
9 12 9 306082
10 12 9 306082
11 12 9 306082
12 12 9 306082
13 12 9 306082
14 12 9 306082
15 12 9 306082
2 13 9 99e550
3 13 9 306082
4 13 9 306082
5 13 9 306082
6 13 9 306082
7 13 9 306082
8 13 9 306082
9 13 9 306082
10 13 9 306082
11 13 9 306082
12 13 9 306082
13 13 9 306082
14 13 9 306082
15 13 9 306082
1 14 9 99e550
2 14 9 99e550
3 14 9 306082
4 14 9 306082
5 14 9 306082
6 14 9 306082
7 14 9 306082
8 14 9 306082
9 14 9 306082
10 14 9 306082
11 14 9 306082
12 14 9 306082
13 14 9 306082
14 14 9 306082
15 14 9 306082
1 15 9 99e550
2 15 9 99e550
3 15 9 306082
4 15 9 306082
5 15 9 306082
6 15 9 306082
7 15 9 306082
8 15 9 306082
9 15 9 306082
10 15 9 306082
11 15 9 306082
12 15 9 306082
13 15 9 306082
14 15 9 306082
15 15 9 306082
12 1 10 306082
13 1 10 306082
14 1 10 306082
15 1 10 306082
9 2 10 306082
10 2 10 99e550
11 2 10 306082
12 2 10 306082
13 2 10 306082
14 2 10 306082
15 2 10 306082
8 3 10 306082
9 3 10 306082
10 3 10 99e550
11 3 10 306082
12 3 10 306082
13 3 10 306082
14 3 10 306082
15 3 10 306082
6 4 10 99e550
7 4 10 99e550
8 4 10 99e550
9 4 10 306082
10 4 10 306082
11 4 10 306082
12 4 10 306082
13 4 10 306082
14 4 10 306082
15 4 10 306082
5 5 10 99e550
6 5 10 99e550
7 5 10 99e550
8 5 10 99e550
9 5 10 99e550
10 5 10 306082
11 5 10 306082
12 5 10 306082
13 5 10 306082
14 5 10 306082
15 5 10 306082
4 6 10 99e550
5 6 10 99e550
6 6 10 99e550
7 6 10 99e550
8 6 10 99e550
9 6 10 99e550
10 6 10 306082
11 6 10 306082
12 6 10 306082
13 6 10 306082
14 6 10 306082
15 6 10 306082
4 7 10 99e550
5 7 10 99e550
6 7 10 99e550
7 7 10 99e550
8 7 10 99e550
9 7 10 306082
10 7 10 306082
11 7 10 306082
12 7 10 306082
13 7 10 306082
14 7 10 306082
15 7 10 306082
3 8 10 306082
4 8 10 99e550
5 8 10 99e550
6 8 10 99e550
7 8 10 99e550
8 8 10 306082
9 8 10 306082
10 8 10 306082
11 8 10 306082
12 8 10 306082
13 8 10 306082
14 8 10 306082
15 8 10 306082
2 9 10 306082
3 9 10 306082
4 9 10 306082
5 9 10 306082
6 9 10 306082
7 9 10 306082
8 9 10 306082
9 9 10 306082
10 9 10 306082
11 9 10 306082
12 9 10 306082
13 9 10 306082
14 9 10 306082
15 9 10 306082
2 10 10 99e550
3 10 10 306082
4 10 10 306082
5 10 10 306082
6 10 10 306082
7 10 10 306082
8 10 10 306082
9 10 10 306082
10 10 10 306082
11 10 10 306082
12 10 10 306082
13 10 10 306082
14 10 10 306082
15 10 10 306082
2 11 10 306082
3 11 10 306082
4 11 10 306082
5 11 10 306082
6 11 10 306082
7 11 10 306082
8 11 10 306082
9 11 10 306082
10 11 10 306082
11 11 10 306082
12 11 10 306082
13 11 10 306082
14 11 10 306082
15 11 10 306082
1 12 10 306082
2 12 10 306082
3 12 10 306082
4 12 10 306082
5 12 10 306082
6 12 10 306082
7 12 10 306082
8 12 10 306082
9 12 10 306082
10 12 10 306082
11 12 10 306082
12 12 10 306082
13 12 10 306082
14 12 10 306082
15 12 10 306082
1 13 10 99e550
2 13 10 99e550
3 13 10 306082
4 13 10 306082
5 13 10 306082
6 13 10 306082
7 13 10 306082
8 13 10 306082
9 13 10 306082
10 13 10 306082
11 13 10 306082
12 13 10 306082
13 13 10 306082
14 13 10 306082
15 13 10 306082
1 14 10 99e550
2 14 10 99e550
3 14 10 306082
4 14 10 306082
5 14 10 306082
6 14 10 306082
7 14 10 306082
8 14 10 306082
9 14 10 306082
10 14 10 306082
11 14 10 306082
12 14 10 306082
13 14 10 306082
14 14 10 306082
15 14 10 306082
1 15 10 99e550
2 15 10 99e550
3 15 10 306082
4 15 10 306082
5 15 10 306082
6 15 10 306082
7 15 10 306082
8 15 10 306082
9 15 10 306082
10 15 10 306082
11 15 10 306082
12 15 10 306082
13 15 10 306082
14 15 10 306082
15 15 10 306082
11 1 11 306082
12 1 11 306082
13 1 11 306082
14 1 11 306082
15 1 11 306082
9 2 11 306082
10 2 11 99e550
11 2 11 306082
12 2 11 306082
13 2 11 306082
14 2 11 306082
15 2 11 306082
7 3 11 99e550
8 3 11 306082
9 3 11 306082
10 3 11 99e550
11 3 11 306082
12 3 11 306082
13 3 11 306082
14 3 11 306082
15 3 11 306082
6 4 11 99e550
7 4 11 99e550
8 4 11 99e550
9 4 11 306082
10 4 11 306082
11 4 11 306082
12 4 11 306082
13 4 11 306082
14 4 11 306082
15 4 11 306082
5 5 11 99e550
6 5 11 99e550
7 5 11 99e550
8 5 11 99e550
9 5 11 99e550
10 5 11 306082
11 5 11 306082
12 5 11 306082
13 5 11 306082
14 5 11 306082
15 5 11 306082
4 6 11 99e550
5 6 11 99e550
6 6 11 99e550
7 6 11 99e550
8 6 11 99e550
9 6 11 99e550
10 6 11 306082
11 6 11 306082
12 6 11 306082
13 6 11 306082
14 6 11 306082
15 6 11 306082
3 7 11 99e550
4 7 11 99e550
5 7 11 99e550
6 7 11 99e550
7 7 11 99e550
8 7 11 99e550
9 7 11 306082
10 7 11 306082
11 7 11 306082
12 7 11 306082
13 7 11 306082
14 7 11 306082
15 7 11 306082
3 8 11 306082
4 8 11 99e550
5 8 11 99e550
6 8 11 99e550
7 8 11 99e550
8 8 11 306082
9 8 11 306082
10 8 11 306082
11 8 11 306082
12 8 11 306082
13 8 11 306082
14 8 11 306082
15 8 11 306082
2 9 11 99e550
3 9 11 306082
4 9 11 306082
5 9 11 306082
6 9 11 306082
7 9 11 306082
8 9 11 306082
9 9 11 306082
10 9 11 306082
11 9 11 306082
12 9 11 306082
13 9 11 306082
14 9 11 306082
15 9 11 306082
2 10 11 99e550
3 10 11 306082
4 10 11 306082
5 10 11 306082
6 10 11 306082
7 10 11 306082
8 10 11 306082
9 10 11 306082
10 10 11 306082
11 10 11 306082
12 10 11 306082
13 10 11 306082
14 10 11 306082
15 10 11 306082
1 11 11 99e550
2 11 11 99e550
3 11 11 306082
4 11 11 306082
5 11 11 306082
6 11 11 306082
7 11 11 306082
8 11 11 306082
9 11 11 306082
10 11 11 306082
11 11 11 306082
12 11 11 306082
13 11 11 306082
14 11 11 306082
15 11 11 306082
1 12 11 306082
2 12 11 306082
3 12 11 306082
4 12 11 306082
5 12 11 306082
6 12 11 306082
7 12 11 306082
8 12 11 306082
9 12 11 306082
10 12 11 306082
11 12 11 306082
12 12 11 306082
13 12 11 306082
14 12 11 306082
15 12 11 306082
1 13 11 306082
2 13 11 306082
3 13 11 306082
4 13 11 306082
5 13 11 306082
6 13 11 306082
7 13 11 306082
8 13 11 306082
9 13 11 306082
10 13 11 306082
11 13 11 306082
12 13 11 306082
13 13 11 306082
14 13 11 306082
15 13 11 306082
1 14 11 306082
2 14 11 306082
3 14 11 306082
4 14 11 306082
5 14 11 306082
6 14 11 306082
7 14 11 306082
8 14 11 306082
9 14 11 306082
10 14 11 306082
11 14 11 306082
12 14 11 306082
13 14 11 306082
14 14 11 306082
15 14 11 306082
1 15 11 306082
2 15 11 306082
3 15 11 306082
4 15 11 306082
5 15 11 306082
6 15 11 306082
7 15 11 306082
8 15 11 306082
9 15 11 306082
10 15 11 306082
11 15 11 306082
12 15 11 306082
13 15 11 306082
14 15 11 306082
15 15 11 306082
14 0 12 306082
15 0 12 306082
10 1 12 99e550
11 1 12 99e550
12 1 12 99e550
13 1 12 306082
14 1 12 306082
15 1 12 306082
8 2 12 306082
9 2 12 306082
10 2 12 306082
11 2 12 306082
12 2 12 306082
13 2 12 306082
14 2 12 306082
15 2 12 306082
7 3 12 306082
8 3 12 306082
9 3 12 306082
10 3 12 306082
11 3 12 306082
12 3 12 306082
13 3 12 306082
14 3 12 306082
15 3 12 306082
5 4 12 99e550
6 4 12 99e550
7 4 12 306082
8 4 12 306082
9 4 12 306082
10 4 12 306082
11 4 12 306082
12 4 12 306082
13 4 12 306082
14 4 12 306082
15 4 12 306082
4 5 12 99e550
5 5 12 99e550
6 5 12 99e550
7 5 12 99e550
8 5 12 306082
9 5 12 306082
10 5 12 306082
11 5 12 306082
12 5 12 306082
13 5 12 306082
14 5 12 306082
15 5 12 306082
4 6 12 99e550
5 6 12 99e550
6 6 12 99e550
7 6 12 99e550
8 6 12 306082
9 6 12 306082
10 6 12 306082
11 6 12 306082
12 6 12 306082
13 6 12 306082
14 6 12 306082
15 6 12 306082
3 7 12 306082
4 7 12 306082
5 7 12 99e550
6 7 12 99e550
7 7 12 306082
8 7 12 306082
9 7 12 306082
10 7 12 306082
11 7 12 306082
12 7 12 306082
13 7 12 306082
14 7 12 306082
15 7 12 306082
2 8 12 306082
3 8 12 306082
4 8 12 306082
5 8 12 306082
6 8 12 306082
7 8 12 306082
8 8 12 306082
9 8 12 306082
10 8 12 306082
11 8 12 306082
12 8 12 306082
13 8 12 306082
14 8 12 306082
15 8 12 306082
2 9 12 99e550
3 9 12 306082
4 9 12 306082
5 9 12 306082
6 9 12 306082
7 9 12 306082
8 9 12 306082
9 9 12 306082
10 9 12 306082
11 9 12 306082
12 9 12 306082
13 9 12 306082
14 9 12 306082
15 9 12 306082
1 10 12 99e550
2 10 12 99e550
3 10 12 306082
4 10 12 306082
5 10 12 306082
6 10 12 306082
7 10 12 306082
8 10 12 306082
9 10 12 306082
10 10 12 306082
11 10 12 306082
12 10 12 306082
13 10 12 306082
14 10 12 306082
15 10 12 306082
1 11 12 99e550
2 11 12 99e550
3 11 12 306082
4 11 12 306082
5 11 12 306082
6 11 12 306082
7 11 12 306082
8 11 12 306082
9 11 12 306082
10 11 12 306082
11 11 12 306082
12 11 12 306082
13 11 12 306082
14 11 12 306082
15 11 12 306082
1 12 12 306082
2 12 12 306082
3 12 12 306082
4 12 12 306082
5 12 12 306082
6 12 12 306082
7 12 12 306082
8 12 12 306082
9 12 12 306082
10 12 12 306082
11 12 12 306082
12 12 12 306082
13 12 12 306082
14 12 12 306082
15 12 12 306082
1 13 12 99e550
2 13 12 306082
3 13 12 306082
4 13 12 306082
5 13 12 306082
6 13 12 306082
7 13 12 306082
8 13 12 306082
9 13 12 306082
10 13 12 306082
11 13 12 306082
12 13 12 306082
13 13 12 306082
14 13 12 306082
15 13 12 306082
0 14 12 99e550
1 14 12 99e550
2 14 12 306082
3 14 12 306082
4 14 12 306082
5 14 12 306082
6 14 12 306082
7 14 12 306082
8 14 12 306082
9 14 12 306082
10 14 12 306082
11 14 12 306082
12 14 12 306082
13 14 12 306082
14 14 12 306082
15 14 12 306082
0 15 12 99e550
1 15 12 99e550
2 15 12 306082
3 15 12 306082
4 15 12 306082
5 15 12 306082
6 15 12 306082
7 15 12 306082
8 15 12 306082
9 15 12 306082
10 15 12 306082
11 15 12 306082
12 15 12 306082
13 15 12 306082
14 15 12 306082
15 15 12 306082
13 0 13 306082
14 0 13 306082
15 0 13 306082
10 1 13 99e550
11 1 13 99e550
12 1 13 99e550
13 1 13 99e550
14 1 13 306082
15 1 13 306082
8 2 13 306082
9 2 13 306082
10 2 13 99e550
11 2 13 99e550
12 2 13 99e550
13 2 13 306082
14 2 13 306082
15 2 13 306082
6 3 13 306082
7 3 13 306082
8 3 13 306082
9 3 13 306082
10 3 13 306082
11 3 13 306082
12 3 13 306082
13 3 13 306082
14 3 13 306082
15 3 13 306082
5 4 13 306082
6 4 13 306082
7 4 13 306082
8 4 13 306082
9 4 13 306082
10 4 13 306082
11 4 13 306082
12 4 13 306082
13 4 13 306082
14 4 13 306082
15 4 13 306082
4 5 13 306082
5 5 13 306082
6 5 13 306082
7 5 13 306082
8 5 13 306082
9 5 13 306082
10 5 13 306082
11 5 13 306082
12 5 13 306082
13 5 13 306082
14 5 13 306082
15 5 13 306082
3 6 13 306082
4 6 13 306082
5 6 13 306082
6 6 13 306082
7 6 13 306082
8 6 13 306082
9 6 13 306082
10 6 13 306082
11 6 13 306082
12 6 13 306082
13 6 13 306082
14 6 13 306082
15 6 13 306082
3 7 13 306082
4 7 13 306082
5 7 13 306082
6 7 13 306082
7 7 13 306082
8 7 13 306082
9 7 13 306082
10 7 13 306082
11 7 13 306082
12 7 13 306082
13 7 13 306082
14 7 13 306082
15 7 13 306082
2 8 13 306082
3 8 13 306082
4 8 13 306082
5 8 13 306082
6 8 13 306082
7 8 13 306082
8 8 13 306082
9 8 13 306082
10 8 13 306082
11 8 13 306082
12 8 13 306082
13 8 13 306082
14 8 13 306082
15 8 13 306082
2 9 13 99e550
3 9 13 306082
4 9 13 306082
5 9 13 306082
6 9 13 306082
7 9 13 306082
8 9 13 306082
9 9 13 306082
10 9 13 306082
11 9 13 306082
12 9 13 306082
13 9 13 306082
14 9 13 306082
15 9 13 306082
1 10 13 99e550
2 10 13 99e550
3 10 13 306082
4 10 13 306082
5 10 13 306082
6 10 13 306082
7 10 13 306082
8 10 13 306082
9 10 13 306082
10 10 13 306082
11 10 13 306082
12 10 13 306082
13 10 13 306082
14 10 13 306082
15 10 13 306082
1 11 13 99e550
2 11 13 99e550
3 11 13 306082
4 11 13 306082
5 11 13 306082
6 11 13 306082
7 11 13 306082
8 11 13 306082
9 11 13 306082
10 11 13 306082
11 11 13 306082
12 11 13 306082
13 11 13 306082
14 11 13 306082
15 11 13 306082
1 12 13 306082
2 12 13 306082
3 12 13 306082
4 12 13 306082
5 12 13 306082
6 12 13 306082
7 12 13 306082
8 12 13 306082
9 12 13 306082
10 12 13 306082
11 12 13 306082
12 12 13 306082
13 12 13 306082
14 12 13 306082
15 12 13 306082
0 13 13 99e550
1 13 13 99e550
2 13 13 306082
3 13 13 306082
4 13 13 306082
5 13 13 306082
6 13 13 306082
7 13 13 306082
8 13 13 306082
9 13 13 306082
10 13 13 306082
11 13 13 306082
12 13 13 306082
13 13 13 306082
14 13 13 306082
15 13 13 306082
0 14 13 99e550
1 14 13 99e550
2 14 13 306082
3 14 13 306082
4 14 13 306082
5 14 13 306082
6 14 13 306082
7 14 13 306082
8 14 13 306082
9 14 13 306082
10 14 13 306082
11 14 13 306082
12 14 13 306082
13 14 13 306082
14 14 13 306082
15 14 13 306082
0 15 13 99e550
1 15 13 99e550
2 15 13 306082
3 15 13 306082
4 15 13 306082
5 15 13 306082
6 15 13 306082
7 15 13 306082
8 15 13 306082
9 15 13 306082
10 15 13 306082
11 15 13 306082
12 15 13 306082
13 15 13 306082
14 15 13 306082
15 15 13 306082
12 0 14 99e550
13 0 14 306082
14 0 14 306082
15 0 14 306082
9 1 14 99e550
10 1 14 99e550
11 1 14 99e550
12 1 14 99e550
13 1 14 99e550
14 1 14 306082
15 1 14 306082
8 2 14 306082
9 2 14 306082
10 2 14 99e550
11 2 14 99e550
12 2 14 99e550
13 2 14 306082
14 2 14 306082
15 2 14 306082
6 3 14 306082
7 3 14 306082
8 3 14 306082
9 3 14 306082
10 3 14 306082
11 3 14 306082
12 3 14 306082
13 3 14 306082
14 3 14 306082
15 3 14 306082
5 4 14 306082
6 4 14 306082
7 4 14 306082
8 4 14 306082
9 4 14 306082
10 4 14 306082
11 4 14 306082
12 4 14 306082
13 4 14 306082
14 4 14 306082
15 4 14 306082
4 5 14 306082
5 5 14 306082
6 5 14 306082
7 5 14 306082
8 5 14 306082
9 5 14 306082
10 5 14 306082
11 5 14 306082
12 5 14 306082
13 5 14 306082
14 5 14 306082
15 5 14 306082
3 6 14 306082
4 6 14 306082
5 6 14 306082
6 6 14 306082
7 6 14 306082
8 6 14 306082
9 6 14 306082
10 6 14 306082
11 6 14 306082
12 6 14 306082
13 6 14 306082
14 6 14 306082
15 6 14 306082
3 7 14 306082
4 7 14 306082
5 7 14 306082
6 7 14 306082
7 7 14 306082
8 7 14 306082
9 7 14 306082
10 7 14 306082
11 7 14 306082
12 7 14 306082
13 7 14 306082
14 7 14 306082
15 7 14 306082
2 8 14 306082
3 8 14 306082
4 8 14 306082
5 8 14 306082
6 8 14 306082
7 8 14 306082
8 8 14 306082
9 8 14 306082
10 8 14 306082
11 8 14 306082
12 8 14 306082
13 8 14 306082
14 8 14 306082
15 8 14 306082
1 9 14 99e550
2 9 14 99e550
3 9 14 306082
4 9 14 306082
5 9 14 306082
6 9 14 99e550
7 9 14 99e550
8 9 14 306082
9 9 14 306082
10 9 14 306082
11 9 14 306082
12 9 14 306082
13 9 14 306082
14 9 14 306082
15 9 14 306082
1 10 14 99e550
2 10 14 99e550
3 10 14 306082
4 10 14 306082
5 10 14 99e550
6 10 14 99e550
7 10 14 99e550
8 10 14 99e550
9 10 14 306082
10 10 14 306082
11 10 14 306082
12 10 14 306082
13 10 14 306082
14 10 14 306082
15 10 14 306082
1 11 14 99e550
2 11 14 99e550
3 11 14 306082
4 11 14 306082
5 11 14 99e550
6 11 14 99e550
7 11 14 99e550
8 11 14 99e550
9 11 14 306082
10 11 14 306082
11 11 14 306082
12 11 14 306082
13 11 14 306082
14 11 14 306082
15 11 14 306082
0 12 14 99e550
1 12 14 99e550
2 12 14 306082
3 12 14 306082
4 12 14 306082
5 12 14 306082
6 12 14 99e550
7 12 14 99e550
8 12 14 306082
9 12 14 306082
10 12 14 306082
11 12 14 306082
12 12 14 306082
13 12 14 306082
14 12 14 306082
15 12 14 306082
0 13 14 99e550
1 13 14 99e550
2 13 14 306082
3 13 14 306082
4 13 14 306082
5 13 14 306082
6 13 14 306082
7 13 14 306082
8 13 14 306082
9 13 14 306082
10 13 14 306082
11 13 14 306082
12 13 14 306082
13 13 14 306082
14 13 14 306082
15 13 14 306082
0 14 14 99e550
1 14 14 99e550
2 14 14 306082
3 14 14 306082
4 14 14 306082
5 14 14 306082
6 14 14 306082
7 14 14 306082
8 14 14 306082
9 14 14 306082
10 14 14 306082
11 14 14 306082
12 14 14 306082
13 14 14 306082
14 14 14 306082
15 14 14 306082
0 15 14 99e550
1 15 14 99e550
2 15 14 306082
3 15 14 306082
4 15 14 306082
5 15 14 306082
6 15 14 306082
7 15 14 306082
8 15 14 306082
9 15 14 306082
10 15 14 306082
11 15 14 306082
12 15 14 306082
13 15 14 306082
14 15 14 306082
15 15 14 306082
12 0 15 99e550
13 0 15 306082
14 0 15 306082
15 0 15 306082
9 1 15 99e550
10 1 15 99e550
11 1 15 99e550
12 1 15 99e550
13 1 15 99e550
14 1 15 306082
15 1 15 306082
7 2 15 306082
8 2 15 306082
9 2 15 306082
10 2 15 99e550
11 2 15 99e550
12 2 15 99e550
13 2 15 306082
14 2 15 306082
15 2 15 306082
6 3 15 306082
7 3 15 306082
8 3 15 306082
9 3 15 306082
10 3 15 306082
11 3 15 306082
12 3 15 306082
13 3 15 306082
14 3 15 306082
15 3 15 306082
5 4 15 306082
6 4 15 306082
7 4 15 306082
8 4 15 306082
9 4 15 306082
10 4 15 306082
11 4 15 306082
12 4 15 306082
13 4 15 306082
14 4 15 306082
15 4 15 306082
4 5 15 306082
5 5 15 306082
6 5 15 306082
7 5 15 306082
8 5 15 306082
9 5 15 306082
10 5 15 306082
11 5 15 306082
12 5 15 306082
13 5 15 306082
14 5 15 306082
15 5 15 306082
3 6 15 306082
4 6 15 306082
5 6 15 306082
6 6 15 306082
7 6 15 306082
8 6 15 306082
9 6 15 306082
10 6 15 306082
11 6 15 306082
12 6 15 306082
13 6 15 306082
14 6 15 306082
15 6 15 306082
2 7 15 306082
3 7 15 306082
4 7 15 306082
5 7 15 306082
6 7 15 306082
7 7 15 306082
8 7 15 306082
9 7 15 306082
10 7 15 306082
11 7 15 306082
12 7 15 306082
13 7 15 306082
14 7 15 306082
15 7 15 306082
2 8 15 306082
3 8 15 306082
4 8 15 306082
5 8 15 99e550
6 8 15 99e550
7 8 15 99e550
8 8 15 99e550
9 8 15 306082
10 8 15 306082
11 8 15 306082
12 8 15 306082
13 8 15 306082
14 8 15 306082
15 8 15 306082
1 9 15 306082
2 9 15 306082
3 9 15 99e550
4 9 15 99e550
5 9 15 99e550
6 9 15 99e550
7 9 15 99e550
8 9 15 99e550
9 9 15 99e550
10 9 15 99e550
11 9 15 306082
12 9 15 306082
13 9 15 306082
14 9 15 306082
15 9 15 306082
1 10 15 99e550
2 10 15 99e550
3 10 15 99e550
4 10 15 99e550
5 10 15 99e550
6 10 15 99e550
7 10 15 99e550
8 10 15 99e550
9 10 15 99e550
10 10 15 99e550
11 10 15 306082
12 10 15 306082
13 10 15 306082
14 10 15 306082
15 10 15 306082
1 11 15 306082
2 11 15 306082
3 11 15 99e550
4 11 15 99e550
5 11 15 99e550
6 11 15 99e550
7 11 15 99e550
8 11 15 99e550
9 11 15 99e550
10 11 15 99e550
11 11 15 306082
12 11 15 306082
13 11 15 306082
14 11 15 306082
15 11 15 306082
0 12 15 306082
1 12 15 306082
2 12 15 306082
3 12 15 99e550
4 12 15 99e550
5 12 15 99e550
6 12 15 99e550
7 12 15 99e550
8 12 15 99e550
9 12 15 99e550
10 12 15 99e550
11 12 15 306082
12 12 15 306082
13 12 15 306082
14 12 15 306082
15 12 15 306082
0 13 15 99e550
1 13 15 99e550
2 13 15 306082
3 13 15 306082
4 13 15 306082
5 13 15 99e550
6 13 15 99e550
7 13 15 99e550
8 13 15 99e550
9 13 15 306082
10 13 15 306082
11 13 15 306082
12 13 15 306082
13 13 15 306082
14 13 15 306082
15 13 15 306082
0 14 15 99e550
1 14 15 99e550
2 14 15 306082
3 14 15 306082
4 14 15 306082
5 14 15 306082
6 14 15 306082
7 14 15 306082
8 14 15 306082
9 14 15 306082
10 14 15 306082
11 14 15 306082
12 14 15 306082
13 14 15 306082
14 14 15 306082
15 14 15 306082
0 15 15 99e550
1 15 15 99e550
2 15 15 306082
3 15 15 306082
4 15 15 306082
5 15 15 306082
6 15 15 306082
7 15 15 306082
8 15 15 306082
9 15 15 306082
10 15 15 306082
11 15 15 306082
12 15 15 306082
13 15 15 306082
14 15 15 306082
15 15 15 306082
16 12 0 ffffff
17 12 0 ffffff
16 13 0 ffffff
17 13 0 ffffff
18 13 0 ffffff
16 14 0 ffffff
17 14 0 ffffff
18 14 0 ffffff
19 14 0 ffffff
16 15 0 ffffff
17 15 0 ffffff
18 15 0 ffffff
19 15 0 ffffff
16 9 1 306082
17 9 1 306082
16 10 1 ffffff
17 10 1 ffffff
18 10 1 ffffff
19 10 1 ffffff
16 11 1 ffffff
17 11 1 ffffff
18 11 1 ffffff
19 11 1 ffffff
20 11 1 ffffff
16 12 1 ffffff
17 12 1 ffffff
18 12 1 ffffff
19 12 1 ffffff
20 12 1 ffffff
21 12 1 ffffff
16 13 1 ffffff
17 13 1 ffffff
18 13 1 ffffff
19 13 1 ffffff
20 13 1 ffffff
21 13 1 ffffff
16 14 1 ffffff
17 14 1 ffffff
18 14 1 ffffff
19 14 1 ffffff
20 14 1 ffffff
21 14 1 ffffff
22 14 1 306082
16 15 1 ffffff
17 15 1 ffffff
18 15 1 ffffff
19 15 1 ffffff
20 15 1 ffffff
21 15 1 ffffff
22 15 1 ffffff
16 7 2 306082
16 8 2 306082
17 8 2 306082
18 8 2 306082
19 8 2 306082
16 9 2 306082
17 9 2 306082
18 9 2 306082
19 9 2 306082
20 9 2 306082
21 9 2 306082
16 10 2 306082
17 10 2 306082
18 10 2 ffffff
19 10 2 ffffff
20 10 2 306082
21 10 2 306082
22 10 2 306082
16 11 2 306082
17 11 2 306082
18 11 2 ffffff
19 11 2 ffffff
20 11 2 ffffff
21 11 2 306082
22 11 2 306082
16 12 2 306082
17 12 2 306082
18 12 2 ffffff
19 12 2 ffffff
20 12 2 ffffff
21 12 2 306082
22 12 2 306082
23 12 2 306082
16 13 2 306082
17 13 2 306082
18 13 2 ffffff
19 13 2 ffffff
20 13 2 ffffff
21 13 2 306082
22 13 2 306082
23 13 2 306082
16 14 2 ffffff
17 14 2 ffffff
18 14 2 ffffff
19 14 2 ffffff
20 14 2 ffffff
21 14 2 ffffff
22 14 2 ffffff
23 14 2 306082
16 15 2 ffffff
17 15 2 ffffff
18 15 2 ffffff
19 15 2 ffffff
20 15 2 ffffff
21 15 2 ffffff
22 15 2 ffffff
23 15 2 ffffff
24 15 2 ffffff
16 6 3 306082
17 6 3 306082
18 6 3 306082
16 7 3 306082
17 7 3 306082
18 7 3 306082
19 7 3 306082
20 7 3 306082
16 8 3 306082
17 8 3 306082
18 8 3 306082
19 8 3 306082
20 8 3 306082
21 8 3 306082
22 8 3 306082
16 9 3 306082
17 9 3 306082
18 9 3 306082
19 9 3 306082
20 9 3 306082
21 9 3 306082
22 9 3 306082
23 9 3 306082
16 10 3 306082
17 10 3 306082
18 10 3 306082
19 10 3 306082
20 10 3 306082
21 10 3 306082
22 10 3 306082
23 10 3 306082
16 11 3 306082
17 11 3 306082
18 11 3 306082
19 11 3 306082
20 11 3 306082
21 11 3 306082
22 11 3 306082
23 11 3 306082
24 11 3 306082
16 12 3 306082
17 12 3 306082
18 12 3 306082
19 12 3 306082
20 12 3 306082
21 12 3 306082
22 12 3 306082
23 12 3 306082
24 12 3 306082
16 13 3 306082
17 13 3 306082
18 13 3 306082
19 13 3 306082
20 13 3 306082
21 13 3 306082
22 13 3 306082
23 13 3 306082
24 13 3 306082
25 13 3 306082
16 14 3 ffffff
17 14 3 ffffff
18 14 3 ffffff
19 14 3 ffffff
20 14 3 ffffff
21 14 3 ffffff
22 14 3 ffffff
23 14 3 306082
24 14 3 306082
25 14 3 306082
16 15 3 ffffff
17 15 3 ffffff
18 15 3 ffffff
19 15 3 ffffff
20 15 3 ffffff
21 15 3 ffffff
22 15 3 ffffff
23 15 3 ffffff
24 15 3 ffffff
25 15 3 ffffff
16 5 4 306082
17 5 4 306082
18 5 4 306082
19 5 4 306082
16 6 4 306082
17 6 4 306082
18 6 4 306082
19 6 4 306082
20 6 4 306082
21 6 4 306082
16 7 4 306082
17 7 4 306082
18 7 4 306082
19 7 4 306082
20 7 4 306082
21 7 4 306082
22 7 4 306082
16 8 4 306082
17 8 4 306082
18 8 4 306082
19 8 4 306082
20 8 4 306082
21 8 4 306082
22 8 4 306082
23 8 4 306082
16 9 4 306082
17 9 4 306082
18 9 4 306082
19 9 4 306082
20 9 4 306082
21 9 4 306082
22 9 4 306082
23 9 4 306082
24 9 4 306082
16 10 4 306082
17 10 4 306082
18 10 4 306082
19 10 4 306082
20 10 4 306082
21 10 4 306082
22 10 4 306082
23 10 4 306082
24 10 4 306082
25 10 4 306082
16 11 4 306082
17 11 4 306082
18 11 4 306082
19 11 4 306082
20 11 4 306082
21 11 4 306082
22 11 4 306082
23 11 4 306082
24 11 4 306082
25 11 4 306082
16 12 4 306082
17 12 4 306082
18 12 4 306082
19 12 4 306082
20 12 4 306082
21 12 4 306082
22 12 4 306082
23 12 4 306082
24 12 4 306082
25 12 4 306082
26 12 4 306082
16 13 4 306082
17 13 4 306082
18 13 4 306082
19 13 4 306082
20 13 4 306082
21 13 4 306082
22 13 4 306082
23 13 4 306082
24 13 4 306082
25 13 4 306082
26 13 4 306082
16 14 4 306082
17 14 4 306082
18 14 4 306082
19 14 4 306082
20 14 4 306082
21 14 4 306082
22 14 4 306082
23 14 4 306082
24 14 4 306082
25 14 4 306082
26 14 4 306082
16 15 4 ffffff
17 15 4 ffffff
18 15 4 ffffff
19 15 4 ffffff
20 15 4 ffffff
21 15 4 ffffff
22 15 4 ffffff
23 15 4 306082
24 15 4 306082
25 15 4 306082
26 15 4 306082
16 4 5 306082
17 4 5 306082
18 4 5 306082
19 4 5 306082
16 5 5 306082
17 5 5 306082
18 5 5 306082
19 5 5 306082
20 5 5 306082
21 5 5 306082
16 6 5 306082
17 6 5 306082
18 6 5 306082
19 6 5 306082
20 6 5 306082
21 6 5 306082
22 6 5 306082
16 7 5 306082
17 7 5 306082
18 7 5 306082
19 7 5 306082
20 7 5 306082
21 7 5 306082
22 7 5 306082
23 7 5 306082
24 7 5 306082
16 8 5 306082
17 8 5 306082
18 8 5 306082
19 8 5 306082
20 8 5 306082
21 8 5 306082
22 8 5 306082
23 8 5 306082
24 8 5 306082
16 9 5 306082
17 9 5 306082
18 9 5 306082
19 9 5 306082
20 9 5 306082
21 9 5 306082
22 9 5 306082
23 9 5 306082
24 9 5 306082
25 9 5 306082
16 10 5 306082
17 10 5 306082
18 10 5 306082
19 10 5 306082
20 10 5 306082
21 10 5 306082
22 10 5 306082
23 10 5 306082
24 10 5 306082
25 10 5 306082
26 10 5 306082
16 11 5 306082
17 11 5 306082
18 11 5 306082
19 11 5 306082
20 11 5 306082
21 11 5 306082
22 11 5 306082
23 11 5 306082
24 11 5 306082
25 11 5 306082
26 11 5 306082
16 12 5 306082
17 12 5 306082
18 12 5 306082
19 12 5 306082
20 12 5 306082
21 12 5 306082
22 12 5 306082
23 12 5 306082
24 12 5 306082
25 12 5 306082
26 12 5 306082
27 12 5 306082
16 13 5 306082
17 13 5 306082
18 13 5 306082
19 13 5 306082
20 13 5 306082
21 13 5 306082
22 13 5 306082
23 13 5 306082
24 13 5 306082
25 13 5 306082
26 13 5 306082
27 13 5 306082
16 14 5 306082
17 14 5 306082
18 14 5 306082
19 14 5 306082
20 14 5 306082
21 14 5 306082
22 14 5 306082
23 14 5 306082
24 14 5 306082
25 14 5 306082
26 14 5 306082
27 14 5 306082
16 15 5 306082
17 15 5 306082
18 15 5 306082
19 15 5 306082
20 15 5 306082
21 15 5 306082
22 15 5 306082
23 15 5 306082
24 15 5 306082
25 15 5 306082
26 15 5 306082
27 15 5 306082
16 3 6 306082
17 3 6 306082
18 3 6 99e550
16 4 6 306082
17 4 6 306082
18 4 6 306082
19 4 6 306082
20 4 6 306082
21 4 6 306082
16 5 6 306082
17 5 6 306082
18 5 6 306082
19 5 6 306082
20 5 6 306082
21 5 6 306082
22 5 6 306082
16 6 6 306082
17 6 6 306082
18 6 6 306082
19 6 6 306082
20 6 6 306082
21 6 6 306082
22 6 6 306082
23 6 6 306082
24 6 6 306082
16 7 6 306082
17 7 6 306082
18 7 6 306082
19 7 6 306082
20 7 6 306082
21 7 6 306082
22 7 6 306082
23 7 6 306082
24 7 6 306082
25 7 6 306082
16 8 6 306082
17 8 6 306082
18 8 6 306082
19 8 6 306082
20 8 6 306082
21 8 6 306082
22 8 6 306082
23 8 6 306082
24 8 6 306082
25 8 6 306082
16 9 6 306082
17 9 6 306082
18 9 6 306082
19 9 6 306082
20 9 6 306082
21 9 6 306082
22 9 6 306082
23 9 6 306082
24 9 6 306082
25 9 6 306082
26 9 6 306082
16 10 6 306082
17 10 6 306082
18 10 6 306082
19 10 6 306082
20 10 6 306082
21 10 6 306082
22 10 6 306082
23 10 6 306082
24 10 6 306082
25 10 6 306082
26 10 6 306082
27 10 6 306082
16 11 6 306082
17 11 6 306082
18 11 6 306082
19 11 6 306082
20 11 6 306082
21 11 6 306082
22 11 6 306082
23 11 6 306082
24 11 6 306082
25 11 6 306082
26 11 6 306082
27 11 6 306082
16 12 6 306082
17 12 6 306082
18 12 6 306082
19 12 6 306082
20 12 6 306082
21 12 6 306082
22 12 6 306082
23 12 6 306082
24 12 6 306082
25 12 6 306082
26 12 6 306082
27 12 6 306082
16 13 6 306082
17 13 6 306082
18 13 6 306082
19 13 6 306082
20 13 6 306082
21 13 6 306082
22 13 6 306082
23 13 6 306082
24 13 6 306082
25 13 6 306082
26 13 6 306082
27 13 6 306082
28 13 6 306082
16 14 6 306082
17 14 6 306082
18 14 6 306082
19 14 6 306082
20 14 6 306082
21 14 6 306082
22 14 6 306082
23 14 6 306082
24 14 6 306082
25 14 6 306082
26 14 6 306082
27 14 6 306082
28 14 6 306082
16 15 6 306082
17 15 6 306082
18 15 6 306082
19 15 6 306082
20 15 6 306082
21 15 6 306082
22 15 6 306082
23 15 6 306082
24 15 6 306082
25 15 6 306082
26 15 6 306082
27 15 6 306082
28 15 6 306082
16 2 7 306082
16 3 7 306082
17 3 7 99e550
18 3 7 99e550
19 3 7 99e550
20 3 7 99e550
16 4 7 306082
17 4 7 306082
18 4 7 99e550
19 4 7 99e550
20 4 7 99e550
21 4 7 99e550
22 4 7 99e550
16 5 7 306082
17 5 7 306082
18 5 7 306082
19 5 7 306082
20 5 7 99e550
21 5 7 99e550
22 5 7 99e550
23 5 7 99e550
24 5 7 99e550
16 6 7 306082
17 6 7 306082
18 6 7 306082
19 6 7 306082
20 6 7 306082
21 6 7 99e550
22 6 7 99e550
23 6 7 99e550
24 6 7 306082
25 6 7 306082
16 7 7 306082
17 7 7 306082
18 7 7 306082
19 7 7 306082
20 7 7 306082
21 7 7 306082
22 7 7 306082
23 7 7 306082
24 7 7 306082
25 7 7 306082
26 7 7 306082
16 8 7 306082
17 8 7 306082
18 8 7 306082
19 8 7 306082
20 8 7 306082
21 8 7 306082
22 8 7 306082
23 8 7 306082
24 8 7 306082
25 8 7 306082
26 8 7 306082
16 9 7 306082
17 9 7 306082
18 9 7 306082
19 9 7 306082
20 9 7 306082
21 9 7 306082
22 9 7 306082
23 9 7 306082
24 9 7 306082
25 9 7 306082
26 9 7 306082
27 9 7 306082
16 10 7 306082
17 10 7 306082
18 10 7 306082
19 10 7 306082
20 10 7 306082
21 10 7 306082
22 10 7 306082
23 10 7 306082
24 10 7 306082
25 10 7 306082
26 10 7 306082
27 10 7 306082
16 11 7 306082
17 11 7 306082
18 11 7 306082
19 11 7 306082
20 11 7 306082
21 11 7 306082
22 11 7 306082
23 11 7 306082
24 11 7 306082
25 11 7 306082
26 11 7 306082
27 11 7 306082
28 11 7 306082
16 12 7 306082
17 12 7 306082
18 12 7 306082
19 12 7 306082
20 12 7 306082
21 12 7 306082
22 12 7 306082
23 12 7 306082
24 12 7 306082
25 12 7 306082
26 12 7 306082
27 12 7 306082
28 12 7 306082
16 13 7 306082
17 13 7 306082
18 13 7 306082
19 13 7 306082
20 13 7 306082
21 13 7 306082
22 13 7 306082
23 13 7 306082
24 13 7 306082
25 13 7 306082
26 13 7 306082
27 13 7 306082
28 13 7 306082
16 14 7 306082
17 14 7 306082
18 14 7 306082
19 14 7 306082
20 14 7 306082
21 14 7 306082
22 14 7 306082
23 14 7 306082
24 14 7 306082
25 14 7 306082
26 14 7 306082
27 14 7 306082
28 14 7 306082
16 15 7 306082
17 15 7 306082
18 15 7 306082
19 15 7 306082
20 15 7 306082
21 15 7 306082
22 15 7 306082
23 15 7 306082
24 15 7 306082
25 15 7 306082
26 15 7 306082
27 15 7 306082
28 15 7 306082
29 15 7 306082
16 2 8 306082
17 2 8 99e550
18 2 8 99e550
19 2 8 99e550
16 3 8 306082
17 3 8 99e550
18 3 8 99e550
19 3 8 99e550
20 3 8 99e550
21 3 8 99e550
22 3 8 99e550
16 4 8 306082
17 4 8 306082
18 4 8 99e550
19 4 8 99e550
20 4 8 99e550
21 4 8 99e550
22 4 8 99e550
23 4 8 99e550
16 5 8 306082
17 5 8 306082
18 5 8 306082
19 5 8 306082
20 5 8 99e550
21 5 8 99e550
22 5 8 99e550
23 5 8 99e550
24 5 8 99e550
16 6 8 306082
17 6 8 306082
18 6 8 306082
19 6 8 306082
20 6 8 306082
21 6 8 99e550
22 6 8 99e550
23 6 8 99e550
24 6 8 306082
25 6 8 306082
16 7 8 306082
17 7 8 306082
18 7 8 306082
19 7 8 306082
20 7 8 306082
21 7 8 306082
22 7 8 306082
23 7 8 306082
24 7 8 306082
25 7 8 306082
26 7 8 306082
16 8 8 306082
17 8 8 306082
18 8 8 306082
19 8 8 306082
20 8 8 306082
21 8 8 306082
22 8 8 306082
23 8 8 306082
24 8 8 306082
25 8 8 306082
26 8 8 306082
27 8 8 306082
16 9 8 306082
17 9 8 306082
18 9 8 306082
19 9 8 306082
20 9 8 306082
21 9 8 306082
22 9 8 306082
23 9 8 306082
24 9 8 306082
25 9 8 306082
26 9 8 306082
27 9 8 306082
28 9 8 306082
16 10 8 306082
17 10 8 306082
18 10 8 306082
19 10 8 306082
20 10 8 306082
21 10 8 306082
22 10 8 306082
23 10 8 306082
24 10 8 306082
25 10 8 306082
26 10 8 306082
27 10 8 306082
28 10 8 306082
16 11 8 306082
17 11 8 306082
18 11 8 306082
19 11 8 306082
20 11 8 306082
21 11 8 306082
22 11 8 306082
23 11 8 306082
24 11 8 306082
25 11 8 306082
26 11 8 306082
27 11 8 306082
28 11 8 306082
16 12 8 306082
17 12 8 306082
18 12 8 306082
19 12 8 306082
20 12 8 306082
21 12 8 306082
22 12 8 306082
23 12 8 306082
24 12 8 306082
25 12 8 306082
26 12 8 306082
27 12 8 306082
28 12 8 306082
29 12 8 306082
16 13 8 306082
17 13 8 306082
18 13 8 306082
19 13 8 306082
20 13 8 306082
21 13 8 306082
22 13 8 306082
23 13 8 306082
24 13 8 306082
25 13 8 306082
26 13 8 306082
27 13 8 306082
28 13 8 306082
29 13 8 306082
16 14 8 306082
17 14 8 306082
18 14 8 306082
19 14 8 306082
20 14 8 306082
21 14 8 306082
22 14 8 306082
23 14 8 306082
24 14 8 306082
25 14 8 306082
26 14 8 306082
27 14 8 306082
28 14 8 306082
29 14 8 306082
16 15 8 306082
17 15 8 306082
18 15 8 306082
19 15 8 306082
20 15 8 306082
21 15 8 306082
22 15 8 306082
23 15 8 306082
24 15 8 306082
25 15 8 306082
26 15 8 306082
27 15 8 306082
28 15 8 306082
29 15 8 306082
16 1 9 306082
17 1 9 306082
16 2 9 306082
17 2 9 99e550
18 2 9 99e550
19 2 9 99e550
20 2 9 99e550
21 2 9 306082
16 3 9 306082
17 3 9 99e550
18 3 9 99e550
19 3 9 99e550
20 3 9 99e550
21 3 9 306082
22 3 9 306082
23 3 9 306082
16 4 9 306082
17 4 9 306082
18 4 9 99e550
19 4 9 99e550
20 4 9 306082
21 4 9 306082
22 4 9 306082
23 4 9 306082
24 4 9 306082
16 5 9 306082
17 5 9 306082
18 5 9 306082
19 5 9 306082
20 5 9 306082
21 5 9 306082
22 5 9 306082
23 5 9 306082
24 5 9 306082
25 5 9 306082
16 6 9 306082
17 6 9 306082
18 6 9 306082
19 6 9 306082
20 6 9 306082
21 6 9 306082
22 6 9 306082
23 6 9 306082
24 6 9 306082
25 6 9 306082
26 6 9 306082
16 7 9 306082
17 7 9 306082
18 7 9 306082
19 7 9 306082
20 7 9 306082
21 7 9 306082
22 7 9 306082
23 7 9 306082
24 7 9 306082
25 7 9 306082
26 7 9 306082
27 7 9 306082
16 8 9 306082
17 8 9 306082
18 8 9 306082
19 8 9 306082
20 8 9 306082
21 8 9 306082
22 8 9 306082
23 8 9 306082
24 8 9 306082
25 8 9 306082
26 8 9 306082
27 8 9 306082
28 8 9 306082
16 9 9 306082
17 9 9 306082
18 9 9 306082
19 9 9 306082
20 9 9 306082
21 9 9 306082
22 9 9 306082
23 9 9 306082
24 9 9 306082
25 9 9 306082
26 9 9 306082
27 9 9 306082
28 9 9 306082
16 10 9 306082
17 10 9 306082
18 10 9 306082
19 10 9 306082
20 10 9 306082
21 10 9 306082
22 10 9 306082
23 10 9 306082
24 10 9 306082
25 10 9 306082
26 10 9 306082
27 10 9 306082
28 10 9 306082
29 10 9 306082
16 11 9 306082
17 11 9 306082
18 11 9 306082
19 11 9 306082
20 11 9 306082
21 11 9 306082
22 11 9 306082
23 11 9 306082
24 11 9 306082
25 11 9 306082
26 11 9 306082
27 11 9 306082
28 11 9 306082
29 11 9 306082
16 12 9 306082
17 12 9 306082
18 12 9 306082
19 12 9 306082
20 12 9 306082
21 12 9 306082
22 12 9 306082
23 12 9 306082
24 12 9 306082
25 12 9 306082
26 12 9 306082
27 12 9 306082
28 12 9 306082
29 12 9 306082
16 13 9 306082
17 13 9 306082
18 13 9 306082
19 13 9 306082
20 13 9 306082
21 13 9 306082
22 13 9 306082
23 13 9 306082
24 13 9 306082
25 13 9 306082
26 13 9 306082
27 13 9 306082
28 13 9 306082
29 13 9 306082
16 14 9 306082
17 14 9 306082
18 14 9 306082
19 14 9 306082
20 14 9 306082
21 14 9 306082
22 14 9 306082
23 14 9 306082
24 14 9 306082
25 14 9 306082
26 14 9 306082
27 14 9 306082
28 14 9 306082
29 14 9 306082
30 14 9 306082
16 15 9 306082
17 15 9 306082
18 15 9 306082
19 15 9 306082
20 15 9 306082
21 15 9 306082
22 15 9 306082
23 15 9 306082
24 15 9 306082
25 15 9 306082
26 15 9 306082
27 15 9 306082
28 15 9 306082
29 15 9 306082
30 15 9 306082
16 1 10 306082
17 1 10 99e550
18 1 10 306082
19 1 10 306082
16 2 10 306082
17 2 10 306082
18 2 10 99e550
19 2 10 99e550
20 2 10 306082
21 2 10 306082
22 2 10 306082
16 3 10 306082
17 3 10 306082
18 3 10 99e550
19 3 10 99e550
20 3 10 306082
21 3 10 306082
22 3 10 306082
23 3 10 306082
16 4 10 306082
17 4 10 306082
18 4 10 306082
19 4 10 306082
20 4 10 306082
21 4 10 306082
22 4 10 306082
23 4 10 306082
24 4 10 306082
25 4 10 306082
16 5 10 306082
17 5 10 306082
18 5 10 306082
19 5 10 306082
20 5 10 306082
21 5 10 306082
22 5 10 306082
23 5 10 306082
24 5 10 306082
25 5 10 306082
26 5 10 306082
16 6 10 306082
17 6 10 306082
18 6 10 306082
19 6 10 306082
20 6 10 306082
21 6 10 306082
22 6 10 306082
23 6 10 306082
24 6 10 306082
25 6 10 306082
26 6 10 306082
27 6 10 306082
16 7 10 306082
17 7 10 306082
18 7 10 306082
19 7 10 306082
20 7 10 306082
21 7 10 306082
22 7 10 306082
23 7 10 306082
24 7 10 306082
25 7 10 306082
26 7 10 306082
27 7 10 306082
16 8 10 306082
17 8 10 306082
18 8 10 306082
19 8 10 306082
20 8 10 306082
21 8 10 306082
22 8 10 306082
23 8 10 306082
24 8 10 306082
25 8 10 306082
26 8 10 306082
27 8 10 306082
28 8 10 306082
16 9 10 306082
17 9 10 306082
18 9 10 306082
19 9 10 306082
20 9 10 306082
21 9 10 306082
22 9 10 306082
23 9 10 306082
24 9 10 306082
25 9 10 306082
26 9 10 306082
27 9 10 306082
28 9 10 306082
29 9 10 306082
16 10 10 306082
17 10 10 306082
18 10 10 306082
19 10 10 306082
20 10 10 306082
21 10 10 306082
22 10 10 306082
23 10 10 306082
24 10 10 306082
25 10 10 306082
26 10 10 306082
27 10 10 306082
28 10 10 306082
29 10 10 306082
16 11 10 306082
17 11 10 306082
18 11 10 306082
19 11 10 306082
20 11 10 306082
21 11 10 306082
22 11 10 306082
23 11 10 306082
24 11 10 306082
25 11 10 306082
26 11 10 306082
27 11 10 306082
28 11 10 306082
29 11 10 306082
16 12 10 306082
17 12 10 306082
18 12 10 306082
19 12 10 306082
20 12 10 306082
21 12 10 306082
22 12 10 306082
23 12 10 306082
24 12 10 306082
25 12 10 306082
26 12 10 306082
27 12 10 306082
28 12 10 306082
29 12 10 306082
30 12 10 306082
16 13 10 306082
17 13 10 306082
18 13 10 306082
19 13 10 306082
20 13 10 306082
21 13 10 306082
22 13 10 306082
23 13 10 306082
24 13 10 306082
25 13 10 306082
26 13 10 306082
27 13 10 306082
28 13 10 306082
29 13 10 306082
30 13 10 306082
16 14 10 306082
17 14 10 306082
18 14 10 306082
19 14 10 306082
20 14 10 306082
21 14 10 306082
22 14 10 306082
23 14 10 306082
24 14 10 306082
25 14 10 306082
26 14 10 306082
27 14 10 306082
28 14 10 306082
29 14 10 306082
30 14 10 306082
16 15 10 306082
17 15 10 306082
18 15 10 306082
19 15 10 306082
20 15 10 306082
21 15 10 306082
22 15 10 306082
23 15 10 306082
24 15 10 306082
25 15 10 306082
26 15 10 306082
27 15 10 306082
28 15 10 306082
29 15 10 306082
30 15 10 306082
16 1 11 306082
17 1 11 306082
18 1 11 306082
19 1 11 306082
20 1 11 306082
16 2 11 306082
17 2 11 306082
18 2 11 306082
19 2 11 306082
20 2 11 306082
21 2 11 306082
22 2 11 306082
16 3 11 306082
17 3 11 306082
18 3 11 306082
19 3 11 306082
20 3 11 306082
21 3 11 306082
22 3 11 306082
23 3 11 306082
24 3 11 306082
16 4 11 306082
17 4 11 306082
18 4 11 306082
19 4 11 306082
20 4 11 306082
21 4 11 306082
22 4 11 306082
23 4 11 306082
24 4 11 306082
25 4 11 306082
16 5 11 306082
17 5 11 306082
18 5 11 306082
19 5 11 306082
20 5 11 306082
21 5 11 306082
22 5 11 306082
23 5 11 306082
24 5 11 306082
25 5 11 306082
26 5 11 306082
16 6 11 306082
17 6 11 306082
18 6 11 306082
19 6 11 306082
20 6 11 306082
21 6 11 306082
22 6 11 306082
23 6 11 306082
24 6 11 306082
25 6 11 306082
26 6 11 306082
27 6 11 306082
16 7 11 306082
17 7 11 306082
18 7 11 306082
19 7 11 306082
20 7 11 306082
21 7 11 306082
22 7 11 306082
23 7 11 306082
24 7 11 306082
25 7 11 306082
26 7 11 306082
27 7 11 306082
28 7 11 306082
16 8 11 306082
17 8 11 306082
18 8 11 306082
19 8 11 306082
20 8 11 306082
21 8 11 306082
22 8 11 306082
23 8 11 306082
24 8 11 306082
25 8 11 306082
26 8 11 306082
27 8 11 306082
28 8 11 306082
16 9 11 306082
17 9 11 306082
18 9 11 306082
19 9 11 306082
20 9 11 306082
21 9 11 306082
22 9 11 306082
23 9 11 306082
24 9 11 306082
25 9 11 306082
26 9 11 306082
27 9 11 306082
28 9 11 306082
29 9 11 306082
16 10 11 306082
17 10 11 306082
18 10 11 306082
19 10 11 306082
20 10 11 306082
21 10 11 306082
22 10 11 306082
23 10 11 306082
24 10 11 306082
25 10 11 306082
26 10 11 306082
27 10 11 306082
28 10 11 306082
29 10 11 306082
16 11 11 306082
17 11 11 306082
18 11 11 306082
19 11 11 306082
20 11 11 306082
21 11 11 306082
22 11 11 306082
23 11 11 306082
24 11 11 306082
25 11 11 306082
26 11 11 306082
27 11 11 306082
28 11 11 306082
29 11 11 306082
30 11 11 306082
16 12 11 306082
17 12 11 306082
18 12 11 306082
19 12 11 306082
20 12 11 306082
21 12 11 306082
22 12 11 306082
23 12 11 306082
24 12 11 306082
25 12 11 306082
26 12 11 306082
27 12 11 306082
28 12 11 306082
29 12 11 306082
30 12 11 306082
16 13 11 306082
17 13 11 306082
18 13 11 306082
19 13 11 306082
20 13 11 306082
21 13 11 306082
22 13 11 306082
23 13 11 306082
24 13 11 306082
25 13 11 306082
26 13 11 306082
27 13 11 306082
28 13 11 306082
29 13 11 306082
30 13 11 306082
16 14 11 306082
17 14 11 306082
18 14 11 306082
19 14 11 306082
20 14 11 306082
21 14 11 306082
22 14 11 306082
23 14 11 306082
24 14 11 306082
25 14 11 306082
26 14 11 306082
27 14 11 306082
28 14 11 306082
29 14 11 306082
30 14 11 306082
16 15 11 306082
17 15 11 306082
18 15 11 306082
19 15 11 306082
20 15 11 306082
21 15 11 306082
22 15 11 306082
23 15 11 306082
24 15 11 306082
25 15 11 306082
26 15 11 306082
27 15 11 306082
28 15 11 306082
29 15 11 306082
30 15 11 306082
16 0 12 306082
17 0 12 306082
16 1 12 306082
17 1 12 306082
18 1 12 306082
19 1 12 306082
20 1 12 306082
21 1 12 306082
16 2 12 306082
17 2 12 306082
18 2 12 306082
19 2 12 306082
20 2 12 306082
21 2 12 306082
22 2 12 306082
23 2 12 99e550
16 3 12 306082
17 3 12 306082
18 3 12 306082
19 3 12 306082
20 3 12 306082
21 3 12 306082
22 3 12 306082
23 3 12 99e550
24 3 12 99e550
16 4 12 306082
17 4 12 306082
18 4 12 306082
19 4 12 306082
20 4 12 306082
21 4 12 306082
22 4 12 306082
23 4 12 306082
24 4 12 306082
25 4 12 306082
26 4 12 306082
16 5 12 306082
17 5 12 306082
18 5 12 306082
19 5 12 306082
20 5 12 306082
21 5 12 306082
22 5 12 306082
23 5 12 306082
24 5 12 306082
25 5 12 306082
26 5 12 306082
27 5 12 306082
16 6 12 306082
17 6 12 306082
18 6 12 306082
19 6 12 306082
20 6 12 306082
21 6 12 306082
22 6 12 306082
23 6 12 306082
24 6 12 306082
25 6 12 306082
26 6 12 306082
27 6 12 306082
16 7 12 306082
17 7 12 306082
18 7 12 306082
19 7 12 306082
20 7 12 306082
21 7 12 306082
22 7 12 306082
23 7 12 306082
24 7 12 306082
25 7 12 306082
26 7 12 306082
27 7 12 306082
28 7 12 306082
16 8 12 306082
17 8 12 306082
18 8 12 306082
19 8 12 306082
20 8 12 306082
21 8 12 306082
22 8 12 306082
23 8 12 306082
24 8 12 306082
25 8 12 306082
26 8 12 306082
27 8 12 306082
28 8 12 306082
29 8 12 306082
16 9 12 306082
17 9 12 306082
18 9 12 306082
19 9 12 306082
20 9 12 306082
21 9 12 306082
22 9 12 306082
23 9 12 306082
24 9 12 306082
25 9 12 306082
26 9 12 306082
27 9 12 306082
28 9 12 306082
29 9 12 306082
16 10 12 306082
17 10 12 306082
18 10 12 306082
19 10 12 306082
20 10 12 306082
21 10 12 306082
22 10 12 306082
23 10 12 306082
24 10 12 306082
25 10 12 306082
26 10 12 306082
27 10 12 306082
28 10 12 306082
29 10 12 306082
30 10 12 306082
16 11 12 306082
17 11 12 306082
18 11 12 306082
19 11 12 306082
20 11 12 306082
21 11 12 306082
22 11 12 306082
23 11 12 306082
24 11 12 306082
25 11 12 306082
26 11 12 306082
27 11 12 306082
28 11 12 306082
29 11 12 306082
30 11 12 306082
16 12 12 306082
17 12 12 306082
18 12 12 306082
19 12 12 306082
20 12 12 306082
21 12 12 306082
22 12 12 306082
23 12 12 306082
24 12 12 306082
25 12 12 306082
26 12 12 306082
27 12 12 306082
28 12 12 306082
29 12 12 306082
30 12 12 306082
16 13 12 306082
17 13 12 306082
18 13 12 306082
19 13 12 306082
20 13 12 306082
21 13 12 306082
22 13 12 306082
23 13 12 306082
24 13 12 306082
25 13 12 306082
26 13 12 306082
27 13 12 306082
28 13 12 306082
29 13 12 306082
30 13 12 306082
16 14 12 306082
17 14 12 306082
18 14 12 306082
19 14 12 306082
20 14 12 306082
21 14 12 306082
22 14 12 306082
23 14 12 306082
24 14 12 306082
25 14 12 306082
26 14 12 306082
27 14 12 306082
28 14 12 306082
29 14 12 306082
30 14 12 306082
31 14 12 306082
16 15 12 306082
17 15 12 306082
18 15 12 306082
19 15 12 306082
20 15 12 306082
21 15 12 306082
22 15 12 306082
23 15 12 306082
24 15 12 306082
25 15 12 306082
26 15 12 306082
27 15 12 306082
28 15 12 306082
29 15 12 306082
30 15 12 306082
31 15 12 306082
16 0 13 306082
17 0 13 306082
18 0 13 306082
16 1 13 306082
17 1 13 306082
18 1 13 306082
19 1 13 306082
20 1 13 306082
21 1 13 306082
16 2 13 306082
17 2 13 306082
18 2 13 306082
19 2 13 306082
20 2 13 306082
21 2 13 306082
22 2 13 306082
23 2 13 99e550
16 3 13 306082
17 3 13 306082
18 3 13 306082
19 3 13 306082
20 3 13 306082
21 3 13 306082
22 3 13 306082
23 3 13 99e550
24 3 13 99e550
25 3 13 99e550
16 4 13 306082
17 4 13 306082
18 4 13 306082
19 4 13 306082
20 4 13 306082
21 4 13 306082
22 4 13 306082
23 4 13 306082
24 4 13 306082
25 4 13 306082
26 4 13 306082
16 5 13 306082
17 5 13 306082
18 5 13 306082
19 5 13 306082
20 5 13 306082
21 5 13 306082
22 5 13 306082
23 5 13 306082
24 5 13 306082
25 5 13 306082
26 5 13 306082
27 5 13 306082
16 6 13 306082
17 6 13 306082
18 6 13 306082
19 6 13 306082
20 6 13 306082
21 6 13 306082
22 6 13 306082
23 6 13 306082
24 6 13 306082
25 6 13 306082
26 6 13 306082
27 6 13 306082
28 6 13 306082
16 7 13 306082
17 7 13 306082
18 7 13 306082
19 7 13 306082
20 7 13 306082
21 7 13 306082
22 7 13 306082
23 7 13 306082
24 7 13 306082
25 7 13 306082
26 7 13 306082
27 7 13 306082
28 7 13 306082
16 8 13 306082
17 8 13 306082
18 8 13 306082
19 8 13 306082
20 8 13 306082
21 8 13 306082
22 8 13 306082
23 8 13 306082
24 8 13 306082
25 8 13 306082
26 8 13 306082
27 8 13 306082
28 8 13 306082
29 8 13 306082
16 9 13 306082
17 9 13 306082
18 9 13 306082
19 9 13 306082
20 9 13 306082
21 9 13 306082
22 9 13 306082
23 9 13 306082
24 9 13 306082
25 9 13 306082
26 9 13 306082
27 9 13 306082
28 9 13 306082
29 9 13 306082
16 10 13 306082
17 10 13 306082
18 10 13 306082
19 10 13 306082
20 10 13 306082
21 10 13 306082
22 10 13 306082
23 10 13 306082
24 10 13 306082
25 10 13 306082
26 10 13 306082
27 10 13 306082
28 10 13 306082
29 10 13 306082
30 10 13 306082
16 11 13 306082
17 11 13 306082
18 11 13 306082
19 11 13 306082
20 11 13 306082
21 11 13 306082
22 11 13 306082
23 11 13 306082
24 11 13 306082
25 11 13 306082
26 11 13 306082
27 11 13 306082
28 11 13 306082
29 11 13 306082
30 11 13 306082
16 12 13 306082
17 12 13 306082
18 12 13 306082
19 12 13 306082
20 12 13 306082
21 12 13 306082
22 12 13 306082
23 12 13 306082
24 12 13 306082
25 12 13 306082
26 12 13 306082
27 12 13 306082
28 12 13 306082
29 12 13 306082
30 12 13 306082
16 13 13 306082
17 13 13 306082
18 13 13 306082
19 13 13 306082
20 13 13 306082
21 13 13 306082
22 13 13 306082
23 13 13 306082
24 13 13 306082
25 13 13 306082
26 13 13 306082
27 13 13 306082
28 13 13 306082
29 13 13 306082
30 13 13 306082
31 13 13 306082
16 14 13 306082
17 14 13 306082
18 14 13 306082
19 14 13 306082
20 14 13 306082
21 14 13 306082
22 14 13 306082
23 14 13 306082
24 14 13 306082
25 14 13 306082
26 14 13 306082
27 14 13 306082
28 14 13 306082
29 14 13 306082
30 14 13 306082
31 14 13 306082
16 15 13 306082
17 15 13 306082
18 15 13 306082
19 15 13 306082
20 15 13 306082
21 15 13 306082
22 15 13 306082
23 15 13 306082
24 15 13 306082
25 15 13 306082
26 15 13 306082
27 15 13 306082
28 15 13 306082
29 15 13 306082
30 15 13 306082
31 15 13 306082
16 0 14 306082
17 0 14 306082
18 0 14 306082
19 0 14 306082
16 1 14 306082
17 1 14 306082
18 1 14 306082
19 1 14 306082
20 1 14 306082
21 1 14 306082
22 1 14 306082
16 2 14 306082
17 2 14 306082
18 2 14 306082
19 2 14 306082
20 2 14 306082
21 2 14 306082
22 2 14 306082
23 2 14 306082
16 3 14 306082
17 3 14 306082
18 3 14 306082
19 3 14 306082
20 3 14 306082
21 3 14 306082
22 3 14 306082
23 3 14 306082
24 3 14 306082
25 3 14 306082
16 4 14 306082
17 4 14 306082
18 4 14 306082
19 4 14 306082
20 4 14 306082
21 4 14 306082
22 4 14 306082
23 4 14 306082
24 4 14 306082
25 4 14 306082
26 4 14 306082
16 5 14 306082
17 5 14 306082
18 5 14 306082
19 5 14 306082
20 5 14 306082
21 5 14 306082
22 5 14 306082
23 5 14 306082
24 5 14 306082
25 5 14 306082
26 5 14 306082
27 5 14 306082
16 6 14 306082
17 6 14 306082
18 6 14 306082
19 6 14 306082
20 6 14 306082
21 6 14 306082
22 6 14 306082
23 6 14 306082
24 6 14 306082
25 6 14 306082
26 6 14 306082
27 6 14 306082
28 6 14 306082
16 7 14 306082
17 7 14 306082
18 7 14 306082
19 7 14 306082
20 7 14 306082
21 7 14 306082
22 7 14 306082
23 7 14 306082
24 7 14 306082
25 7 14 306082
26 7 14 306082
27 7 14 306082
28 7 14 306082
16 8 14 306082
17 8 14 306082
18 8 14 306082
19 8 14 306082
20 8 14 306082
21 8 14 306082
22 8 14 306082
23 8 14 306082
24 8 14 306082
25 8 14 306082
26 8 14 306082
27 8 14 306082
28 8 14 306082
29 8 14 306082
16 9 14 306082
17 9 14 306082
18 9 14 306082
19 9 14 306082
20 9 14 306082
21 9 14 306082
22 9 14 306082
23 9 14 306082
24 9 14 306082
25 9 14 306082
26 9 14 306082
27 9 14 306082
28 9 14 306082
29 9 14 306082
30 9 14 306082
16 10 14 306082
17 10 14 306082
18 10 14 306082
19 10 14 306082
20 10 14 306082
21 10 14 306082
22 10 14 306082
23 10 14 306082
24 10 14 306082
25 10 14 306082
26 10 14 306082
27 10 14 306082
28 10 14 306082
29 10 14 306082
30 10 14 306082
16 11 14 306082
17 11 14 306082
18 11 14 306082
19 11 14 306082
20 11 14 306082
21 11 14 306082
22 11 14 306082
23 11 14 306082
24 11 14 306082
25 11 14 306082
26 11 14 306082
27 11 14 306082
28 11 14 306082
29 11 14 306082
30 11 14 306082
16 12 14 306082
17 12 14 306082
18 12 14 306082
19 12 14 306082
20 12 14 306082
21 12 14 306082
22 12 14 306082
23 12 14 306082
24 12 14 306082
25 12 14 306082
26 12 14 306082
27 12 14 306082
28 12 14 306082
29 12 14 306082
30 12 14 306082
31 12 14 306082
16 13 14 306082
17 13 14 306082
18 13 14 306082
19 13 14 306082
20 13 14 306082
21 13 14 306082
22 13 14 306082
23 13 14 306082
24 13 14 306082
25 13 14 306082
26 13 14 306082
27 13 14 306082
28 13 14 306082
29 13 14 306082
30 13 14 306082
31 13 14 306082
16 14 14 306082
17 14 14 306082
18 14 14 306082
19 14 14 306082
20 14 14 306082
21 14 14 306082
22 14 14 306082
23 14 14 306082
24 14 14 306082
25 14 14 306082
26 14 14 306082
27 14 14 306082
28 14 14 306082
29 14 14 306082
30 14 14 306082
31 14 14 306082
16 15 14 306082
17 15 14 306082
18 15 14 306082
19 15 14 306082
20 15 14 306082
21 15 14 306082
22 15 14 306082
23 15 14 306082
24 15 14 306082
25 15 14 306082
26 15 14 306082
27 15 14 306082
28 15 14 306082
29 15 14 306082
30 15 14 306082
31 15 14 306082
16 0 15 306082
17 0 15 306082
18 0 15 306082
19 0 15 306082
16 1 15 306082
17 1 15 306082
18 1 15 306082
19 1 15 306082
20 1 15 306082
21 1 15 306082
22 1 15 306082
16 2 15 306082
17 2 15 306082
18 2 15 306082
19 2 15 306082
20 2 15 306082
21 2 15 306082
22 2 15 306082
23 2 15 306082
24 2 15 306082
16 3 15 306082
17 3 15 306082
18 3 15 306082
19 3 15 306082
20 3 15 306082
21 3 15 306082
22 3 15 306082
23 3 15 306082
24 3 15 306082
25 3 15 306082
16 4 15 306082
17 4 15 306082
18 4 15 306082
19 4 15 306082
20 4 15 306082
21 4 15 306082
22 4 15 306082
23 4 15 306082
24 4 15 306082
25 4 15 306082
26 4 15 306082
16 5 15 306082
17 5 15 306082
18 5 15 306082
19 5 15 306082
20 5 15 306082
21 5 15 306082
22 5 15 306082
23 5 15 306082
24 5 15 306082
25 5 15 306082
26 5 15 306082
27 5 15 306082
16 6 15 306082
17 6 15 306082
18 6 15 306082
19 6 15 306082
20 6 15 306082
21 6 15 306082
22 6 15 306082
23 6 15 306082
24 6 15 306082
25 6 15 306082
26 6 15 306082
27 6 15 306082
28 6 15 306082
16 7 15 306082
17 7 15 306082
18 7 15 306082
19 7 15 306082
20 7 15 306082
21 7 15 306082
22 7 15 306082
23 7 15 306082
24 7 15 306082
25 7 15 306082
26 7 15 306082
27 7 15 306082
28 7 15 306082
29 7 15 306082
16 8 15 306082
17 8 15 306082
18 8 15 306082
19 8 15 306082
20 8 15 306082
21 8 15 306082
22 8 15 306082
23 8 15 306082
24 8 15 306082
25 8 15 306082
26 8 15 306082
27 8 15 306082
28 8 15 306082
29 8 15 306082
16 9 15 306082
17 9 15 306082
18 9 15 306082
19 9 15 306082
20 9 15 306082
21 9 15 306082
22 9 15 306082
23 9 15 306082
24 9 15 306082
25 9 15 306082
26 9 15 306082
27 9 15 306082
28 9 15 306082
29 9 15 306082
30 9 15 306082
16 10 15 306082
17 10 15 306082
18 10 15 306082
19 10 15 306082
20 10 15 306082
21 10 15 306082
22 10 15 306082
23 10 15 306082
24 10 15 306082
25 10 15 306082
26 10 15 306082
27 10 15 306082
28 10 15 306082
29 10 15 306082
30 10 15 306082
16 11 15 306082
17 11 15 306082
18 11 15 306082
19 11 15 306082
20 11 15 306082
21 11 15 306082
22 11 15 306082
23 11 15 306082
24 11 15 306082
25 11 15 306082
26 11 15 306082
27 11 15 306082
28 11 15 306082
29 11 15 306082
30 11 15 306082
16 12 15 306082
17 12 15 306082
18 12 15 306082
19 12 15 306082
20 12 15 306082
21 12 15 306082
22 12 15 306082
23 12 15 306082
24 12 15 306082
25 12 15 306082
26 12 15 306082
27 12 15 306082
28 12 15 306082
29 12 15 306082
30 12 15 306082
31 12 15 306082
16 13 15 306082
17 13 15 306082
18 13 15 306082
19 13 15 306082
20 13 15 306082
21 13 15 306082
22 13 15 306082
23 13 15 306082
24 13 15 306082
25 13 15 306082
26 13 15 306082
27 13 15 306082
28 13 15 306082
29 13 15 306082
30 13 15 306082
31 13 15 306082
16 14 15 306082
17 14 15 306082
18 14 15 306082
19 14 15 306082
20 14 15 306082
21 14 15 306082
22 14 15 306082
23 14 15 306082
24 14 15 306082
25 14 15 306082
26 14 15 306082
27 14 15 306082
28 14 15 306082
29 14 15 306082
30 14 15 306082
31 14 15 306082
16 15 15 306082
17 15 15 306082
18 15 15 306082
19 15 15 306082
20 15 15 306082
21 15 15 306082
22 15 15 306082
23 15 15 306082
24 15 15 306082
25 15 15 306082
26 15 15 306082
27 15 15 306082
28 15 15 306082
29 15 15 306082
30 15 15 306082
31 15 15 306082
12 16 0 ffffff
13 16 0 ffffff
14 16 0 ffffff
15 16 0 ffffff
12 17 0 ffffff
13 17 0 ffffff
14 17 0 ffffff
15 17 0 ffffff
13 18 0 ffffff
14 18 0 ffffff
15 18 0 ffffff
14 19 0 ffffff
15 19 0 ffffff
9 16 1 306082
10 16 1 306082
11 16 1 306082
12 16 1 306082
13 16 1 ffffff
14 16 1 ffffff
15 16 1 ffffff
9 17 1 306082
10 17 1 306082
11 17 1 306082
12 17 1 306082
13 17 1 306082
14 17 1 ffffff
15 17 1 ffffff
10 18 1 306082
11 18 1 306082
12 18 1 306082
13 18 1 ffffff
14 18 1 ffffff
15 18 1 ffffff
10 19 1 306082
11 19 1 306082
12 19 1 ffffff
13 19 1 ffffff
14 19 1 ffffff
15 19 1 ffffff
11 20 1 306082
12 20 1 306082
13 20 1 ffffff
14 20 1 ffffff
15 20 1 ffffff
12 21 1 306082
13 21 1 306082
14 21 1 ffffff
15 21 1 306082
14 22 1 306082
15 22 1 306082
7 16 2 306082
8 16 2 306082
9 16 2 306082
10 16 2 306082
11 16 2 ffffff
12 16 2 ffffff
13 16 2 ffffff
14 16 2 ffffff
15 16 2 ffffff
8 17 2 306082
9 17 2 306082
10 17 2 306082
11 17 2 306082
12 17 2 ffffff
13 17 2 ffffff
14 17 2 ffffff
15 17 2 ffffff
8 18 2 306082
9 18 2 306082
10 18 2 306082
11 18 2 306082
12 18 2 306082
13 18 2 306082
14 18 2 306082
15 18 2 ffffff
8 19 2 306082
9 19 2 306082
10 19 2 306082
11 19 2 306082
12 19 2 306082
13 19 2 306082
14 19 2 306082
15 19 2 306082
9 20 2 306082
10 20 2 306082
11 20 2 306082
12 20 2 306082
13 20 2 306082
14 20 2 306082
15 20 2 306082
9 21 2 306082
10 21 2 306082
11 21 2 306082
12 21 2 306082
13 21 2 306082
14 21 2 306082
15 21 2 306082
10 22 2 306082
11 22 2 306082
12 22 2 306082
13 22 2 306082
14 22 2 306082
15 22 2 306082
12 23 2 306082
13 23 2 306082
14 23 2 306082
15 23 2 306082
15 24 2 306082
6 16 3 306082
7 16 3 306082
8 16 3 306082
9 16 3 306082
10 16 3 306082
11 16 3 ffffff
12 16 3 ffffff
13 16 3 ffffff
14 16 3 ffffff
15 16 3 ffffff
6 17 3 306082
7 17 3 306082
8 17 3 306082
9 17 3 306082
10 17 3 306082
11 17 3 306082
12 17 3 ffffff
13 17 3 ffffff
14 17 3 ffffff
15 17 3 ffffff
6 18 3 306082
7 18 3 306082
8 18 3 306082
9 18 3 306082
10 18 3 306082
11 18 3 306082
12 18 3 306082
13 18 3 306082
14 18 3 306082
15 18 3 ffffff
7 19 3 306082
8 19 3 306082
9 19 3 306082
10 19 3 306082
11 19 3 306082
12 19 3 306082
13 19 3 306082
14 19 3 306082
15 19 3 306082
7 20 3 306082
8 20 3 306082
9 20 3 306082
10 20 3 306082
11 20 3 306082
12 20 3 306082
13 20 3 306082
14 20 3 306082
15 20 3 306082
8 21 3 306082
9 21 3 306082
10 21 3 306082
11 21 3 306082
12 21 3 306082
13 21 3 306082
14 21 3 306082
15 21 3 306082
8 22 3 306082
9 22 3 306082
10 22 3 306082
11 22 3 306082
12 22 3 306082
13 22 3 306082
14 22 3 306082
15 22 3 306082
9 23 3 306082
10 23 3 306082
11 23 3 306082
12 23 3 306082
13 23 3 306082
14 23 3 306082
15 23 3 306082
11 24 3 306082
12 24 3 306082
13 24 3 306082
14 24 3 306082
15 24 3 306082
13 25 3 306082
14 25 3 306082
15 25 3 306082
5 16 4 306082
6 16 4 306082
7 16 4 306082
8 16 4 306082
9 16 4 306082
10 16 4 306082
11 16 4 306082
12 16 4 306082
13 16 4 306082
14 16 4 ffffff
15 16 4 ffffff
5 17 4 306082
6 17 4 306082
7 17 4 306082
8 17 4 306082
9 17 4 306082
10 17 4 306082
11 17 4 306082
12 17 4 306082
13 17 4 306082
14 17 4 306082
15 17 4 ffffff
5 18 4 306082
6 18 4 306082
7 18 4 306082
8 18 4 306082
9 18 4 306082
10 18 4 306082
11 18 4 306082
12 18 4 306082
13 18 4 306082
14 18 4 306082
15 18 4 306082
5 19 4 306082
6 19 4 306082
7 19 4 306082
8 19 4 306082
9 19 4 306082
10 19 4 306082
11 19 4 306082
12 19 4 306082
13 19 4 306082
14 19 4 306082
15 19 4 306082
6 20 4 306082
7 20 4 306082
8 20 4 306082
9 20 4 306082
10 20 4 306082
11 20 4 306082
12 20 4 306082
13 20 4 306082
14 20 4 306082
15 20 4 306082
6 21 4 306082
7 21 4 306082
8 21 4 306082
9 21 4 306082
10 21 4 306082
11 21 4 306082
12 21 4 306082
13 21 4 306082
14 21 4 306082
15 21 4 306082
7 22 4 306082
8 22 4 306082
9 22 4 306082
10 22 4 306082
11 22 4 306082
12 22 4 306082
13 22 4 306082
14 22 4 306082
15 22 4 306082
8 23 4 306082
9 23 4 306082
10 23 4 306082
11 23 4 306082
12 23 4 306082
13 23 4 306082
14 23 4 306082
15 23 4 306082
9 24 4 306082
10 24 4 306082
11 24 4 306082
12 24 4 306082
13 24 4 306082
14 24 4 306082
15 24 4 306082
10 25 4 306082
11 25 4 306082
12 25 4 306082
13 25 4 306082
14 25 4 306082
15 25 4 306082
12 26 4 306082
13 26 4 306082
14 26 4 306082
15 26 4 306082
4 16 5 306082
5 16 5 306082
6 16 5 306082
7 16 5 306082
8 16 5 306082
9 16 5 306082
10 16 5 306082
11 16 5 306082
12 16 5 306082
13 16 5 306082
14 16 5 306082
15 16 5 306082
4 17 5 306082
5 17 5 306082
6 17 5 306082
7 17 5 306082
8 17 5 306082
9 17 5 306082
10 17 5 306082
11 17 5 306082
12 17 5 306082
13 17 5 306082
14 17 5 306082
15 17 5 306082
4 18 5 306082
5 18 5 306082
6 18 5 306082
7 18 5 306082
8 18 5 306082
9 18 5 306082
10 18 5 306082
11 18 5 306082
12 18 5 306082
13 18 5 306082
14 18 5 306082
15 18 5 306082
4 19 5 306082
5 19 5 306082
6 19 5 306082
7 19 5 306082
8 19 5 306082
9 19 5 306082
10 19 5 306082
11 19 5 306082
12 19 5 306082
13 19 5 306082
14 19 5 306082
15 19 5 306082
5 20 5 306082
6 20 5 306082
7 20 5 306082
8 20 5 306082
9 20 5 306082
10 20 5 306082
11 20 5 306082
12 20 5 306082
13 20 5 306082
14 20 5 306082
15 20 5 306082
5 21 5 306082
6 21 5 306082
7 21 5 306082
8 21 5 306082
9 21 5 306082
10 21 5 306082
11 21 5 306082
12 21 5 306082
13 21 5 306082
14 21 5 306082
15 21 5 306082
6 22 5 306082
7 22 5 306082
8 22 5 306082
9 22 5 306082
10 22 5 306082
11 22 5 306082
12 22 5 306082
13 22 5 306082
14 22 5 306082
15 22 5 306082
7 23 5 306082
8 23 5 306082
9 23 5 306082
10 23 5 306082
11 23 5 306082
12 23 5 306082
13 23 5 306082
14 23 5 306082
15 23 5 306082
7 24 5 306082
8 24 5 306082
9 24 5 306082
10 24 5 306082
11 24 5 306082
12 24 5 306082
13 24 5 306082
14 24 5 306082
15 24 5 306082
9 25 5 306082
10 25 5 306082
11 25 5 306082
12 25 5 306082
13 25 5 306082
14 25 5 306082
15 25 5 306082
10 26 5 306082
11 26 5 306082
12 26 5 306082
13 26 5 306082
14 26 5 306082
15 26 5 306082
12 27 5 306082
13 27 5 306082
14 27 5 306082
15 27 5 306082
3 16 6 306082
4 16 6 306082
5 16 6 306082
6 16 6 306082
7 16 6 306082
8 16 6 306082
9 16 6 306082
10 16 6 306082
11 16 6 306082
12 16 6 306082
13 16 6 306082
14 16 6 306082
15 16 6 306082
3 17 6 306082
4 17 6 306082
5 17 6 306082
6 17 6 306082
7 17 6 306082
8 17 6 306082
9 17 6 306082
10 17 6 306082
11 17 6 306082
12 17 6 306082
13 17 6 306082
14 17 6 306082
15 17 6 306082
3 18 6 306082
4 18 6 306082
5 18 6 306082
6 18 6 306082
7 18 6 306082
8 18 6 306082
9 18 6 306082
10 18 6 306082
11 18 6 306082
12 18 6 306082
13 18 6 306082
14 18 6 306082
15 18 6 306082
4 19 6 306082
5 19 6 306082
6 19 6 306082
7 19 6 306082
8 19 6 306082
9 19 6 306082
10 19 6 306082
11 19 6 306082
12 19 6 306082
13 19 6 306082
14 19 6 306082
15 19 6 306082
4 20 6 306082
5 20 6 306082
6 20 6 306082
7 20 6 306082
8 20 6 306082
9 20 6 306082
10 20 6 306082
11 20 6 306082
12 20 6 306082
13 20 6 306082
14 20 6 306082
15 20 6 306082
4 21 6 306082
5 21 6 306082
6 21 6 306082
7 21 6 306082
8 21 6 306082
9 21 6 306082
10 21 6 306082
11 21 6 306082
12 21 6 306082
13 21 6 306082
14 21 6 306082
15 21 6 306082
5 22 6 306082
6 22 6 306082
7 22 6 306082
8 22 6 306082
9 22 6 306082
10 22 6 306082
11 22 6 306082
12 22 6 306082
13 22 6 306082
14 22 6 306082
15 22 6 306082
6 23 6 306082
7 23 6 306082
8 23 6 306082
9 23 6 306082
10 23 6 306082
11 23 6 306082
12 23 6 306082
13 23 6 306082
14 23 6 306082
15 23 6 306082
6 24 6 306082
7 24 6 306082
8 24 6 306082
9 24 6 306082
10 24 6 306082
11 24 6 306082
12 24 6 306082
13 24 6 306082
14 24 6 306082
15 24 6 306082
7 25 6 306082
8 25 6 306082
9 25 6 306082
10 25 6 306082
11 25 6 306082
12 25 6 306082
13 25 6 306082
14 25 6 306082
15 25 6 306082
9 26 6 306082
10 26 6 306082
11 26 6 306082
12 26 6 306082
13 26 6 306082
14 26 6 306082
15 26 6 306082
10 27 6 306082
11 27 6 306082
12 27 6 306082
13 27 6 306082
14 27 6 306082
15 27 6 306082
13 28 6 306082
14 28 6 306082
15 28 6 306082
2 16 7 306082
3 16 7 306082
4 16 7 306082
5 16 7 306082
6 16 7 306082
7 16 7 306082
8 16 7 306082
9 16 7 306082
10 16 7 306082
11 16 7 306082
12 16 7 306082
13 16 7 306082
14 16 7 306082
15 16 7 306082
3 17 7 306082
4 17 7 306082
5 17 7 306082
6 17 7 306082
7 17 7 306082
8 17 7 306082
9 17 7 306082
10 17 7 306082
11 17 7 306082
12 17 7 306082
13 17 7 306082
14 17 7 306082
15 17 7 306082
3 18 7 306082
4 18 7 306082
5 18 7 306082
6 18 7 306082
7 18 7 306082
8 18 7 306082
9 18 7 306082
10 18 7 306082
11 18 7 306082
12 18 7 306082
13 18 7 306082
14 18 7 306082
15 18 7 306082
3 19 7 306082
4 19 7 306082
5 19 7 306082
6 19 7 306082
7 19 7 306082
8 19 7 306082
9 19 7 306082
10 19 7 306082
11 19 7 306082
12 19 7 306082
13 19 7 306082
14 19 7 306082
15 19 7 306082
3 20 7 306082
4 20 7 306082
5 20 7 306082
6 20 7 306082
7 20 7 306082
8 20 7 306082
9 20 7 306082
10 20 7 306082
11 20 7 306082
12 20 7 306082
13 20 7 306082
14 20 7 306082
15 20 7 306082
4 21 7 306082
5 21 7 306082
6 21 7 306082
7 21 7 306082
8 21 7 306082
9 21 7 306082
10 21 7 306082
11 21 7 306082
12 21 7 306082
13 21 7 306082
14 21 7 306082
15 21 7 306082
4 22 7 306082
5 22 7 306082
6 22 7 306082
7 22 7 306082
8 22 7 306082
9 22 7 306082
10 22 7 306082
11 22 7 306082
12 22 7 306082
13 22 7 306082
14 22 7 306082
15 22 7 306082
5 23 7 306082
6 23 7 306082
7 23 7 306082
8 23 7 306082
9 23 7 306082
10 23 7 306082
11 23 7 306082
12 23 7 306082
13 23 7 306082
14 23 7 306082
15 23 7 306082
5 24 7 306082
6 24 7 306082
7 24 7 306082
8 24 7 306082
9 24 7 306082
10 24 7 306082
11 24 7 306082
12 24 7 306082
13 24 7 306082
14 24 7 306082
15 24 7 306082
6 25 7 306082
7 25 7 306082
8 25 7 306082
9 25 7 306082
10 25 7 306082
11 25 7 306082
12 25 7 306082
13 25 7 306082
14 25 7 306082
15 25 7 306082
7 26 7 306082
8 26 7 306082
9 26 7 306082
10 26 7 306082
11 26 7 306082
12 26 7 306082
13 26 7 306082
14 26 7 306082
15 26 7 306082
9 27 7 306082
10 27 7 306082
11 27 7 306082
12 27 7 306082
13 27 7 306082
14 27 7 306082
15 27 7 306082
11 28 7 306082
12 28 7 306082
13 28 7 306082
14 28 7 306082
15 28 7 306082
15 29 7 306082
2 16 8 306082
3 16 8 306082
4 16 8 306082
5 16 8 306082
6 16 8 306082
7 16 8 306082
8 16 8 306082
9 16 8 306082
10 16 8 306082
11 16 8 306082
12 16 8 306082
13 16 8 306082
14 16 8 306082
15 16 8 306082
2 17 8 306082
3 17 8 306082
4 17 8 306082
5 17 8 306082
6 17 8 306082
7 17 8 306082
8 17 8 306082
9 17 8 306082
10 17 8 306082
11 17 8 306082
12 17 8 306082
13 17 8 306082
14 17 8 306082
15 17 8 306082
2 18 8 306082
3 18 8 306082
4 18 8 306082
5 18 8 306082
6 18 8 306082
7 18 8 306082
8 18 8 306082
9 18 8 306082
10 18 8 306082
11 18 8 306082
12 18 8 306082
13 18 8 306082
14 18 8 306082
15 18 8 306082
2 19 8 306082
3 19 8 306082
4 19 8 306082
5 19 8 306082
6 19 8 306082
7 19 8 306082
8 19 8 306082
9 19 8 306082
10 19 8 306082
11 19 8 306082
12 19 8 306082
13 19 8 306082
14 19 8 306082
15 19 8 306082
3 20 8 306082
4 20 8 306082
5 20 8 306082
6 20 8 306082
7 20 8 306082
8 20 8 306082
9 20 8 306082
10 20 8 306082
11 20 8 306082
12 20 8 306082
13 20 8 306082
14 20 8 306082
15 20 8 306082
3 21 8 306082
4 21 8 306082
5 21 8 306082
6 21 8 306082
7 21 8 306082
8 21 8 306082
9 21 8 306082
10 21 8 306082
11 21 8 306082
12 21 8 306082
13 21 8 306082
14 21 8 306082
15 21 8 306082
3 22 8 306082
4 22 8 306082
5 22 8 306082
6 22 8 306082
7 22 8 306082
8 22 8 306082
9 22 8 306082
10 22 8 306082
11 22 8 306082
12 22 8 306082
13 22 8 306082
14 22 8 306082
15 22 8 306082
4 23 8 306082
5 23 8 306082
6 23 8 306082
7 23 8 306082
8 23 8 306082
9 23 8 306082
10 23 8 306082
11 23 8 306082
12 23 8 306082
13 23 8 306082
14 23 8 306082
15 23 8 306082
5 24 8 306082
6 24 8 306082
7 24 8 306082
8 24 8 306082
9 24 8 306082
10 24 8 306082
11 24 8 306082
12 24 8 306082
13 24 8 306082
14 24 8 306082
15 24 8 306082
6 25 8 306082
7 25 8 306082
8 25 8 306082
9 25 8 306082
10 25 8 306082
11 25 8 306082
12 25 8 306082
13 25 8 306082
14 25 8 306082
15 25 8 306082
7 26 8 306082
8 26 8 306082
9 26 8 306082
10 26 8 306082
11 26 8 306082
12 26 8 306082
13 26 8 306082
14 26 8 306082
15 26 8 306082
8 27 8 306082
9 27 8 306082
10 27 8 306082
11 27 8 306082
12 27 8 306082
13 27 8 306082
14 27 8 306082
15 27 8 306082
9 28 8 306082
10 28 8 306082
11 28 8 306082
12 28 8 306082
13 28 8 306082
14 28 8 306082
15 28 8 306082
12 29 8 306082
13 29 8 306082
14 29 8 306082
15 29 8 306082
1 16 9 99e550
2 16 9 99e550
3 16 9 306082
4 16 9 306082
5 16 9 306082
6 16 9 306082
7 16 9 306082
8 16 9 306082
9 16 9 306082
10 16 9 306082
11 16 9 306082
12 16 9 306082
13 16 9 306082
14 16 9 306082
15 16 9 306082
1 17 9 306082
2 17 9 306082
3 17 9 306082
4 17 9 306082
5 17 9 306082
6 17 9 306082
7 17 9 306082
8 17 9 306082
9 17 9 306082
10 17 9 306082
11 17 9 306082
12 17 9 306082
13 17 9 306082
14 17 9 306082
15 17 9 306082
2 18 9 306082
3 18 9 306082
4 18 9 306082
5 18 9 306082
6 18 9 306082
7 18 9 306082
8 18 9 306082
9 18 9 306082
10 18 9 306082
11 18 9 306082
12 18 9 306082
13 18 9 306082
14 18 9 306082
15 18 9 306082
2 19 9 306082
3 19 9 306082
4 19 9 306082
5 19 9 306082
6 19 9 306082
7 19 9 306082
8 19 9 306082
9 19 9 306082
10 19 9 306082
11 19 9 306082
12 19 9 306082
13 19 9 306082
14 19 9 306082
15 19 9 306082
2 20 9 306082
3 20 9 306082
4 20 9 306082
5 20 9 306082
6 20 9 306082
7 20 9 306082
8 20 9 306082
9 20 9 306082
10 20 9 306082
11 20 9 306082
12 20 9 306082
13 20 9 306082
14 20 9 306082
15 20 9 306082
2 21 9 306082
3 21 9 306082
4 21 9 306082
5 21 9 306082
6 21 9 306082
7 21 9 306082
8 21 9 306082
9 21 9 306082
10 21 9 306082
11 21 9 306082
12 21 9 306082
13 21 9 306082
14 21 9 306082
15 21 9 306082
3 22 9 306082
4 22 9 306082
5 22 9 306082
6 22 9 306082
7 22 9 306082
8 22 9 306082
9 22 9 306082
10 22 9 306082
11 22 9 306082
12 22 9 306082
13 22 9 306082
14 22 9 306082
15 22 9 306082
3 23 9 306082
4 23 9 306082
5 23 9 306082
6 23 9 306082
7 23 9 306082
8 23 9 306082
9 23 9 306082
10 23 9 306082
11 23 9 306082
12 23 9 306082
13 23 9 306082
14 23 9 306082
15 23 9 306082
4 24 9 306082
5 24 9 306082
6 24 9 306082
7 24 9 306082
8 24 9 306082
9 24 9 306082
10 24 9 306082
11 24 9 306082
12 24 9 306082
13 24 9 306082
14 24 9 306082
15 24 9 306082
5 25 9 306082
6 25 9 306082
7 25 9 306082
8 25 9 306082
9 25 9 306082
10 25 9 306082
11 25 9 306082
12 25 9 306082
13 25 9 306082
14 25 9 306082
15 25 9 306082
6 26 9 306082
7 26 9 306082
8 26 9 306082
9 26 9 306082
10 26 9 306082
11 26 9 306082
12 26 9 306082
13 26 9 306082
14 26 9 306082
15 26 9 306082
7 27 9 306082
8 27 9 306082
9 27 9 306082
10 27 9 306082
11 27 9 306082
12 27 9 306082
13 27 9 306082
14 27 9 306082
15 27 9 306082
8 28 9 306082
9 28 9 306082
10 28 9 306082
11 28 9 306082
12 28 9 306082
13 28 9 306082
14 28 9 306082
15 28 9 306082
10 29 9 306082
11 29 9 306082
12 29 9 306082
13 29 9 306082
14 29 9 306082
15 29 9 306082
14 30 9 306082
15 30 9 306082
1 16 10 99e550
2 16 10 99e550
3 16 10 306082
4 16 10 306082
5 16 10 306082
6 16 10 306082
7 16 10 306082
8 16 10 306082
9 16 10 306082
10 16 10 306082
11 16 10 306082
12 16 10 306082
13 16 10 306082
14 16 10 306082
15 16 10 306082
1 17 10 306082
2 17 10 306082
3 17 10 306082
4 17 10 306082
5 17 10 306082
6 17 10 306082
7 17 10 306082
8 17 10 306082
9 17 10 306082
10 17 10 306082
11 17 10 306082
12 17 10 306082
13 17 10 306082
14 17 10 306082
15 17 10 306082
1 18 10 99e550
2 18 10 306082
3 18 10 306082
4 18 10 306082
5 18 10 306082
6 18 10 306082
7 18 10 306082
8 18 10 306082
9 18 10 306082
10 18 10 306082
11 18 10 306082
12 18 10 306082
13 18 10 306082
14 18 10 306082
15 18 10 306082
1 19 10 99e550
2 19 10 306082
3 19 10 306082
4 19 10 306082
5 19 10 306082
6 19 10 306082
7 19 10 306082
8 19 10 306082
9 19 10 306082
10 19 10 306082
11 19 10 306082
12 19 10 306082
13 19 10 306082
14 19 10 306082
15 19 10 306082
2 20 10 306082
3 20 10 306082
4 20 10 306082
5 20 10 306082
6 20 10 306082
7 20 10 306082
8 20 10 306082
9 20 10 306082
10 20 10 306082
11 20 10 306082
12 20 10 306082
13 20 10 306082
14 20 10 306082
15 20 10 306082
2 21 10 306082
3 21 10 306082
4 21 10 306082
5 21 10 306082
6 21 10 306082
7 21 10 306082
8 21 10 306082
9 21 10 306082
10 21 10 306082
11 21 10 306082
12 21 10 306082
13 21 10 306082
14 21 10 306082
15 21 10 306082
2 22 10 306082
3 22 10 306082
4 22 10 306082
5 22 10 306082
6 22 10 306082
7 22 10 306082
8 22 10 306082
9 22 10 306082
10 22 10 306082
11 22 10 306082
12 22 10 306082
13 22 10 306082
14 22 10 306082
15 22 10 306082
3 23 10 306082
4 23 10 306082
5 23 10 306082
6 23 10 306082
7 23 10 306082
8 23 10 306082
9 23 10 306082
10 23 10 306082
11 23 10 306082
12 23 10 306082
13 23 10 306082
14 23 10 306082
15 23 10 306082
4 24 10 306082
5 24 10 306082
6 24 10 306082
7 24 10 306082
8 24 10 306082
9 24 10 306082
10 24 10 306082
11 24 10 306082
12 24 10 306082
13 24 10 306082
14 24 10 306082
15 24 10 306082
4 25 10 306082
5 25 10 306082
6 25 10 306082
7 25 10 306082
8 25 10 306082
9 25 10 306082
10 25 10 306082
11 25 10 306082
12 25 10 306082
13 25 10 306082
14 25 10 306082
15 25 10 306082
5 26 10 306082
6 26 10 306082
7 26 10 306082
8 26 10 306082
9 26 10 306082
10 26 10 306082
11 26 10 306082
12 26 10 306082
13 26 10 306082
14 26 10 306082
15 26 10 306082
6 27 10 306082
7 27 10 306082
8 27 10 306082
9 27 10 306082
10 27 10 306082
11 27 10 306082
12 27 10 306082
13 27 10 306082
14 27 10 306082
15 27 10 306082
8 28 10 306082
9 28 10 306082
10 28 10 306082
11 28 10 306082
12 28 10 306082
13 28 10 306082
14 28 10 306082
15 28 10 306082
9 29 10 306082
10 29 10 306082
11 29 10 306082
12 29 10 306082
13 29 10 306082
14 29 10 306082
15 29 10 306082
12 30 10 306082
13 30 10 306082
14 30 10 306082
15 30 10 306082
1 16 11 306082
2 16 11 306082
3 16 11 306082
4 16 11 306082
5 16 11 306082
6 16 11 306082
7 16 11 306082
8 16 11 306082
9 16 11 306082
10 16 11 306082
11 16 11 306082
12 16 11 306082
13 16 11 306082
14 16 11 306082
15 16 11 306082
1 17 11 99e550
2 17 11 306082
3 17 11 306082
4 17 11 306082
5 17 11 306082
6 17 11 306082
7 17 11 306082
8 17 11 306082
9 17 11 306082
10 17 11 306082
11 17 11 306082
12 17 11 306082
13 17 11 306082
14 17 11 306082
15 17 11 306082
1 18 11 99e550
2 18 11 306082
3 18 11 306082
4 18 11 306082
5 18 11 306082
6 18 11 306082
7 18 11 306082
8 18 11 306082
9 18 11 306082
10 18 11 306082
11 18 11 306082
12 18 11 306082
13 18 11 306082
14 18 11 306082
15 18 11 306082
1 19 11 99e550
2 19 11 306082
3 19 11 306082
4 19 11 306082
5 19 11 306082
6 19 11 306082
7 19 11 306082
8 19 11 306082
9 19 11 306082
10 19 11 306082
11 19 11 306082
12 19 11 306082
13 19 11 306082
14 19 11 306082
15 19 11 306082
1 20 11 99e550
2 20 11 306082
3 20 11 306082
4 20 11 306082
5 20 11 306082
6 20 11 306082
7 20 11 306082
8 20 11 306082
9 20 11 306082
10 20 11 306082
11 20 11 306082
12 20 11 306082
13 20 11 306082
14 20 11 306082
15 20 11 306082
2 21 11 306082
3 21 11 306082
4 21 11 306082
5 21 11 306082
6 21 11 306082
7 21 11 306082
8 21 11 306082
9 21 11 306082
10 21 11 306082
11 21 11 306082
12 21 11 306082
13 21 11 306082
14 21 11 306082
15 21 11 306082
2 22 11 306082
3 22 11 306082
4 22 11 306082
5 22 11 306082
6 22 11 306082
7 22 11 306082
8 22 11 306082
9 22 11 306082
10 22 11 306082
11 22 11 306082
12 22 11 306082
13 22 11 306082
14 22 11 306082
15 22 11 306082
3 23 11 306082
4 23 11 306082
5 23 11 306082
6 23 11 306082
7 23 11 306082
8 23 11 306082
9 23 11 306082
10 23 11 306082
11 23 11 306082
12 23 11 306082
13 23 11 306082
14 23 11 306082
15 23 11 306082
3 24 11 306082
4 24 11 306082
5 24 11 306082
6 24 11 306082
7 24 11 306082
8 24 11 306082
9 24 11 306082
10 24 11 306082
11 24 11 306082
12 24 11 306082
13 24 11 306082
14 24 11 306082
15 24 11 306082
4 25 11 306082
5 25 11 306082
6 25 11 306082
7 25 11 306082
8 25 11 306082
9 25 11 306082
10 25 11 306082
11 25 11 306082
12 25 11 306082
13 25 11 306082
14 25 11 306082
15 25 11 306082
5 26 11 306082
6 26 11 306082
7 26 11 306082
8 26 11 306082
9 26 11 306082
10 26 11 306082
11 26 11 306082
12 26 11 306082
13 26 11 306082
14 26 11 306082
15 26 11 306082
6 27 11 306082
7 27 11 306082
8 27 11 306082
9 27 11 306082
10 27 11 306082
11 27 11 306082
12 27 11 306082
13 27 11 306082
14 27 11 306082
15 27 11 306082
7 28 11 306082
8 28 11 306082
9 28 11 306082
10 28 11 306082
11 28 11 306082
12 28 11 306082
13 28 11 306082
14 28 11 306082
15 28 11 306082
9 29 11 306082
10 29 11 306082
11 29 11 306082
12 29 11 306082
13 29 11 306082
14 29 11 306082
15 29 11 306082
11 30 11 306082
12 30 11 306082
13 30 11 306082
14 30 11 306082
15 30 11 306082
0 16 12 99e550
1 16 12 99e550
2 16 12 306082
3 16 12 306082
4 16 12 306082
5 16 12 306082
6 16 12 306082
7 16 12 306082
8 16 12 306082
9 16 12 306082
10 16 12 306082
11 16 12 306082
12 16 12 306082
13 16 12 306082
14 16 12 306082
15 16 12 306082
0 17 12 306082
1 17 12 306082
2 17 12 306082
3 17 12 306082
4 17 12 306082
5 17 12 306082
6 17 12 306082
7 17 12 306082
8 17 12 306082
9 17 12 306082
10 17 12 306082
11 17 12 306082
12 17 12 306082
13 17 12 306082
14 17 12 306082
15 17 12 306082
1 18 12 99e550
2 18 12 306082
3 18 12 306082
4 18 12 306082
5 18 12 306082
6 18 12 306082
7 18 12 306082
8 18 12 306082
9 18 12 306082
10 18 12 306082
11 18 12 306082
12 18 12 306082
13 18 12 306082
14 18 12 306082
15 18 12 306082
1 19 12 99e550
2 19 12 306082
3 19 12 306082
4 19 12 306082
5 19 12 306082
6 19 12 306082
7 19 12 306082
8 19 12 306082
9 19 12 306082
10 19 12 306082
11 19 12 306082
12 19 12 306082
13 19 12 306082
14 19 12 306082
15 19 12 306082
1 20 12 99e550
2 20 12 306082
3 20 12 306082
4 20 12 306082
5 20 12 306082
6 20 12 306082
7 20 12 306082
8 20 12 306082
9 20 12 306082
10 20 12 306082
11 20 12 306082
12 20 12 306082
13 20 12 306082
14 20 12 306082
15 20 12 306082
1 21 12 306082
2 21 12 306082
3 21 12 306082
4 21 12 306082
5 21 12 306082
6 21 12 306082
7 21 12 306082
8 21 12 306082
9 21 12 306082
10 21 12 306082
11 21 12 306082
12 21 12 306082
13 21 12 306082
14 21 12 306082
15 21 12 306082
2 22 12 99e550
3 22 12 306082
4 22 12 306082
5 22 12 306082
6 22 12 306082
7 22 12 306082
8 22 12 306082
9 22 12 306082
10 22 12 306082
11 22 12 306082
12 22 12 306082
13 22 12 306082
14 22 12 306082
15 22 12 306082
2 23 12 99e550
3 23 12 306082
4 23 12 306082
5 23 12 306082
6 23 12 306082
7 23 12 306082
8 23 12 306082
9 23 12 306082
10 23 12 306082
11 23 12 306082
12 23 12 306082
13 23 12 306082
14 23 12 306082
15 23 12 306082
3 24 12 306082
4 24 12 306082
5 24 12 306082
6 24 12 306082
7 24 12 306082
8 24 12 306082
9 24 12 306082
10 24 12 306082
11 24 12 306082
12 24 12 306082
13 24 12 306082
14 24 12 306082
15 24 12 306082
4 25 12 306082
5 25 12 306082
6 25 12 306082
7 25 12 306082
8 25 12 306082
9 25 12 306082
10 25 12 306082
11 25 12 306082
12 25 12 306082
13 25 12 306082
14 25 12 306082
15 25 12 306082
4 26 12 306082
5 26 12 306082
6 26 12 306082
7 26 12 306082
8 26 12 306082
9 26 12 306082
10 26 12 306082
11 26 12 306082
12 26 12 306082
13 26 12 306082
14 26 12 306082
15 26 12 306082
5 27 12 306082
6 27 12 306082
7 27 12 306082
8 27 12 306082
9 27 12 306082
10 27 12 306082
11 27 12 306082
12 27 12 306082
13 27 12 306082
14 27 12 306082
15 27 12 306082
7 28 12 306082
8 28 12 306082
9 28 12 306082
10 28 12 306082
11 28 12 306082
12 28 12 306082
13 28 12 306082
14 28 12 306082
15 28 12 306082
8 29 12 306082
9 29 12 306082
10 29 12 306082
11 29 12 306082
12 29 12 306082
13 29 12 306082
14 29 12 306082
15 29 12 306082
10 30 12 306082
11 30 12 306082
12 30 12 306082
13 30 12 306082
14 30 12 306082
15 30 12 306082
14 31 12 306082
15 31 12 306082
0 16 13 99e550
1 16 13 99e550
2 16 13 306082
3 16 13 306082
4 16 13 306082
5 16 13 306082
6 16 13 306082
7 16 13 306082
8 16 13 306082
9 16 13 306082
10 16 13 306082
11 16 13 306082
12 16 13 306082
13 16 13 306082
14 16 13 306082
15 16 13 306082
0 17 13 99e550
1 17 13 99e550
2 17 13 306082
3 17 13 306082
4 17 13 306082
5 17 13 306082
6 17 13 306082
7 17 13 306082
8 17 13 306082
9 17 13 306082
10 17 13 306082
11 17 13 306082
12 17 13 306082
13 17 13 306082
14 17 13 306082
15 17 13 306082
0 18 13 99e550
1 18 13 99e550
2 18 13 306082
3 18 13 306082
4 18 13 306082
5 18 13 306082
6 18 13 306082
7 18 13 306082
8 18 13 306082
9 18 13 306082
10 18 13 306082
11 18 13 306082
12 18 13 306082
13 18 13 306082
14 18 13 306082
15 18 13 306082
1 19 13 99e550
2 19 13 306082
3 19 13 306082
4 19 13 306082
5 19 13 306082
6 19 13 306082
7 19 13 306082
8 19 13 306082
9 19 13 306082
10 19 13 306082
11 19 13 306082
12 19 13 306082
13 19 13 306082
14 19 13 306082
15 19 13 306082
1 20 13 99e550
2 20 13 306082
3 20 13 306082
4 20 13 306082
5 20 13 306082
6 20 13 306082
7 20 13 306082
8 20 13 306082
9 20 13 306082
10 20 13 306082
11 20 13 306082
12 20 13 306082
13 20 13 306082
14 20 13 306082
15 20 13 306082
1 21 13 306082
2 21 13 306082
3 21 13 306082
4 21 13 306082
5 21 13 306082
6 21 13 306082
7 21 13 306082
8 21 13 306082
9 21 13 306082
10 21 13 306082
11 21 13 306082
12 21 13 306082
13 21 13 306082
14 21 13 306082
15 21 13 306082
2 22 13 99e550
3 22 13 306082
4 22 13 306082
5 22 13 306082
6 22 13 306082
7 22 13 306082
8 22 13 306082
9 22 13 306082
10 22 13 306082
11 22 13 306082
12 22 13 306082
13 22 13 306082
14 22 13 306082
15 22 13 306082
2 23 13 99e550
3 23 13 306082
4 23 13 306082
5 23 13 306082
6 23 13 306082
7 23 13 306082
8 23 13 306082
9 23 13 306082
10 23 13 306082
11 23 13 306082
12 23 13 306082
13 23 13 306082
14 23 13 306082
15 23 13 306082
3 24 13 306082
4 24 13 306082
5 24 13 306082
6 24 13 306082
7 24 13 306082
8 24 13 306082
9 24 13 306082
10 24 13 306082
11 24 13 306082
12 24 13 306082
13 24 13 306082
14 24 13 306082
15 24 13 306082
3 25 13 306082
4 25 13 306082
5 25 13 306082
6 25 13 306082
7 25 13 306082
8 25 13 306082
9 25 13 306082
10 25 13 306082
11 25 13 306082
12 25 13 306082
13 25 13 306082
14 25 13 306082
15 25 13 306082
4 26 13 306082
5 26 13 306082
6 26 13 306082
7 26 13 306082
8 26 13 306082
9 26 13 306082
10 26 13 306082
11 26 13 306082
12 26 13 306082
13 26 13 306082
14 26 13 306082
15 26 13 306082
5 27 13 306082
6 27 13 306082
7 27 13 306082
8 27 13 306082
9 27 13 306082
10 27 13 306082
11 27 13 306082
12 27 13 306082
13 27 13 306082
14 27 13 306082
15 27 13 306082
6 28 13 306082
7 28 13 306082
8 28 13 306082
9 28 13 306082
10 28 13 306082
11 28 13 306082
12 28 13 306082
13 28 13 306082
14 28 13 306082
15 28 13 306082
8 29 13 306082
9 29 13 306082
10 29 13 306082
11 29 13 306082
12 29 13 306082
13 29 13 306082
14 29 13 306082
15 29 13 306082
10 30 13 306082
11 30 13 306082
12 30 13 306082
13 30 13 306082
14 30 13 306082
15 30 13 306082
13 31 13 306082
14 31 13 306082
15 31 13 306082
0 16 14 99e550
1 16 14 99e550
2 16 14 306082
3 16 14 306082
4 16 14 306082
5 16 14 306082
6 16 14 306082
7 16 14 306082
8 16 14 306082
9 16 14 306082
10 16 14 306082
11 16 14 306082
12 16 14 306082
13 16 14 306082
14 16 14 306082
15 16 14 306082
0 17 14 99e550
1 17 14 99e550
2 17 14 306082
3 17 14 306082
4 17 14 306082
5 17 14 306082
6 17 14 306082
7 17 14 306082
8 17 14 306082
9 17 14 306082
10 17 14 306082
11 17 14 306082
12 17 14 306082
13 17 14 306082
14 17 14 306082
15 17 14 306082
0 18 14 99e550
1 18 14 99e550
2 18 14 306082
3 18 14 306082
4 18 14 306082
5 18 14 306082
6 18 14 306082
7 18 14 306082
8 18 14 306082
9 18 14 306082
10 18 14 306082
11 18 14 306082
12 18 14 306082
13 18 14 306082
14 18 14 306082
15 18 14 306082
0 19 14 99e550
1 19 14 99e550
2 19 14 306082
3 19 14 306082
4 19 14 306082
5 19 14 306082
6 19 14 306082
7 19 14 306082
8 19 14 306082
9 19 14 306082
10 19 14 306082
11 19 14 306082
12 19 14 306082
13 19 14 306082
14 19 14 306082
15 19 14 306082
1 20 14 99e550
2 20 14 306082
3 20 14 306082
4 20 14 306082
5 20 14 306082
6 20 14 306082
7 20 14 306082
8 20 14 306082
9 20 14 306082
10 20 14 306082
11 20 14 306082
12 20 14 306082
13 20 14 306082
14 20 14 306082
15 20 14 306082
1 21 14 306082
2 21 14 306082
3 21 14 306082
4 21 14 306082
5 21 14 306082
6 21 14 306082
7 21 14 306082
8 21 14 306082
9 21 14 306082
10 21 14 306082
11 21 14 306082
12 21 14 306082
13 21 14 306082
14 21 14 306082
15 21 14 306082
1 22 14 306082
2 22 14 99e550
3 22 14 306082
4 22 14 306082
5 22 14 306082
6 22 14 306082
7 22 14 306082
8 22 14 306082
9 22 14 306082
10 22 14 306082
11 22 14 306082
12 22 14 306082
13 22 14 306082
14 22 14 306082
15 22 14 306082
2 23 14 99e550
3 23 14 306082
4 23 14 306082
5 23 14 306082
6 23 14 306082
7 23 14 306082
8 23 14 306082
9 23 14 306082
10 23 14 306082
11 23 14 306082
12 23 14 306082
13 23 14 306082
14 23 14 306082
15 23 14 306082
3 24 14 306082
4 24 14 306082
5 24 14 306082
6 24 14 306082
7 24 14 306082
8 24 14 306082
9 24 14 306082
10 24 14 306082
11 24 14 306082
12 24 14 306082
13 24 14 306082
14 24 14 306082
15 24 14 306082
3 25 14 306082
4 25 14 306082
5 25 14 306082
6 25 14 306082
7 25 14 306082
8 25 14 306082
9 25 14 306082
10 25 14 306082
11 25 14 306082
12 25 14 306082
13 25 14 306082
14 25 14 306082
15 25 14 306082
4 26 14 306082
5 26 14 306082
6 26 14 306082
7 26 14 306082
8 26 14 306082
9 26 14 306082
10 26 14 306082
11 26 14 306082
12 26 14 306082
13 26 14 306082
14 26 14 306082
15 26 14 306082
5 27 14 306082
6 27 14 306082
7 27 14 306082
8 27 14 306082
9 27 14 306082
10 27 14 306082
11 27 14 306082
12 27 14 306082
13 27 14 306082
14 27 14 306082
15 27 14 306082
6 28 14 306082
7 28 14 306082
8 28 14 306082
9 28 14 306082
10 28 14 306082
11 28 14 306082
12 28 14 306082
13 28 14 306082
14 28 14 306082
15 28 14 306082
8 29 14 306082
9 29 14 306082
10 29 14 306082
11 29 14 306082
12 29 14 306082
13 29 14 306082
14 29 14 306082
15 29 14 306082
9 30 14 306082
10 30 14 306082
11 30 14 306082
12 30 14 306082
13 30 14 306082
14 30 14 306082
15 30 14 306082
12 31 14 306082
13 31 14 306082
14 31 14 306082
15 31 14 306082
0 16 15 99e550
1 16 15 99e550
2 16 15 306082
3 16 15 306082
4 16 15 306082
5 16 15 306082
6 16 15 306082
7 16 15 306082
8 16 15 306082
9 16 15 306082
10 16 15 306082
11 16 15 306082
12 16 15 306082
13 16 15 306082
14 16 15 306082
15 16 15 306082
0 17 15 99e550
1 17 15 99e550
2 17 15 306082
3 17 15 306082
4 17 15 306082
5 17 15 306082
6 17 15 306082
7 17 15 306082
8 17 15 306082
9 17 15 306082
10 17 15 306082
11 17 15 306082
12 17 15 306082
13 17 15 306082
14 17 15 306082
15 17 15 306082
0 18 15 99e550
1 18 15 99e550
2 18 15 306082
3 18 15 306082
4 18 15 306082
5 18 15 306082
6 18 15 306082
7 18 15 306082
8 18 15 306082
9 18 15 306082
10 18 15 306082
11 18 15 306082
12 18 15 306082
13 18 15 306082
14 18 15 306082
15 18 15 306082
0 19 15 99e550
1 19 15 99e550
2 19 15 306082
3 19 15 306082
4 19 15 306082
5 19 15 306082
6 19 15 306082
7 19 15 306082
8 19 15 306082
9 19 15 306082
10 19 15 306082
11 19 15 306082
12 19 15 306082
13 19 15 306082
14 19 15 306082
15 19 15 306082
1 20 15 99e550
2 20 15 306082
3 20 15 306082
4 20 15 306082
5 20 15 306082
6 20 15 306082
7 20 15 306082
8 20 15 306082
9 20 15 306082
10 20 15 306082
11 20 15 306082
12 20 15 306082
13 20 15 306082
14 20 15 306082
15 20 15 306082
1 21 15 306082
2 21 15 306082
3 21 15 306082
4 21 15 306082
5 21 15 306082
6 21 15 306082
7 21 15 306082
8 21 15 306082
9 21 15 306082
10 21 15 306082
11 21 15 306082
12 21 15 306082
13 21 15 306082
14 21 15 306082
15 21 15 306082
1 22 15 306082
2 22 15 306082
3 22 15 306082
4 22 15 306082
5 22 15 306082
6 22 15 306082
7 22 15 306082
8 22 15 306082
9 22 15 306082
10 22 15 306082
11 22 15 306082
12 22 15 306082
13 22 15 306082
14 22 15 306082
15 22 15 306082
2 23 15 306082
3 23 15 306082
4 23 15 306082
5 23 15 306082
6 23 15 306082
7 23 15 306082
8 23 15 306082
9 23 15 306082
10 23 15 306082
11 23 15 306082
12 23 15 306082
13 23 15 306082
14 23 15 306082
15 23 15 306082
2 24 15 99e550
3 24 15 99e550
4 24 15 306082
5 24 15 306082
6 24 15 306082
7 24 15 306082
8 24 15 306082
9 24 15 306082
10 24 15 306082
11 24 15 306082
12 24 15 306082
13 24 15 306082
14 24 15 306082
15 24 15 306082
3 25 15 99e550
4 25 15 306082
5 25 15 306082
6 25 15 306082
7 25 15 306082
8 25 15 306082
9 25 15 306082
10 25 15 306082
11 25 15 306082
12 25 15 306082
13 25 15 306082
14 25 15 306082
15 25 15 306082
4 26 15 306082
5 26 15 306082
6 26 15 306082
7 26 15 306082
8 26 15 306082
9 26 15 306082
10 26 15 306082
11 26 15 306082
12 26 15 306082
13 26 15 306082
14 26 15 306082
15 26 15 306082
5 27 15 306082
6 27 15 306082
7 27 15 306082
8 27 15 306082
9 27 15 306082
10 27 15 306082
11 27 15 306082
12 27 15 306082
13 27 15 306082
14 27 15 306082
15 27 15 306082
6 28 15 306082
7 28 15 306082
8 28 15 306082
9 28 15 306082
10 28 15 306082
11 28 15 306082
12 28 15 306082
13 28 15 306082
14 28 15 306082
15 28 15 306082
7 29 15 306082
8 29 15 306082
9 29 15 306082
10 29 15 306082
11 29 15 306082
12 29 15 306082
13 29 15 306082
14 29 15 306082
15 29 15 306082
9 30 15 306082
10 30 15 306082
11 30 15 306082
12 30 15 306082
13 30 15 306082
14 30 15 306082
15 30 15 306082
12 31 15 306082
13 31 15 306082
14 31 15 306082
15 31 15 306082
16 16 0 ffffff
17 16 0 ffffff
18 16 0 ffffff
19 16 0 ffffff
16 17 0 ffffff
17 17 0 ffffff
18 17 0 ffffff
19 17 0 ffffff
16 18 0 ffffff
17 18 0 ffffff
18 18 0 ffffff
16 19 0 ffffff
17 19 0 ffffff
16 16 1 ffffff
17 16 1 ffffff
18 16 1 ffffff
19 16 1 ffffff
20 16 1 ffffff
21 16 1 ffffff
22 16 1 ffffff
16 17 1 ffffff
17 17 1 ffffff
18 17 1 ffffff
19 17 1 ffffff
20 17 1 ffffff
21 17 1 ffffff
22 17 1 ffffff
16 18 1 306082
17 18 1 ffffff
18 18 1 ffffff
19 18 1 306082
20 18 1 306082
21 18 1 306082
16 19 1 ffffff
17 19 1 ffffff
18 19 1 ffffff
19 19 1 306082
20 19 1 306082
21 19 1 306082
16 20 1 306082
17 20 1 306082
18 20 1 306082
19 20 1 306082
20 20 1 306082
16 21 1 306082
17 21 1 306082
18 21 1 306082
19 21 1 306082
16 22 1 306082
17 22 1 306082
16 16 2 ffffff
17 16 2 ffffff
18 16 2 ffffff
19 16 2 ffffff
20 16 2 ffffff
21 16 2 ffffff
22 16 2 ffffff
23 16 2 ffffff
24 16 2 ffffff
16 17 2 ffffff
17 17 2 ffffff
18 17 2 ffffff
19 17 2 ffffff
20 17 2 ffffff
21 17 2 ffffff
22 17 2 ffffff
23 17 2 ffffff
16 18 2 ffffff
17 18 2 ffffff
18 18 2 ffffff
19 18 2 ffffff
20 18 2 ffffff
21 18 2 ffffff
22 18 2 ffffff
23 18 2 306082
16 19 2 306082
17 19 2 306082
18 19 2 306082
19 19 2 306082
20 19 2 306082
21 19 2 306082
22 19 2 306082
23 19 2 306082
16 20 2 306082
17 20 2 306082
18 20 2 306082
19 20 2 306082
20 20 2 306082
21 20 2 306082
22 20 2 306082
16 21 2 306082
17 21 2 306082
18 21 2 306082
19 21 2 306082
20 21 2 306082
21 21 2 306082
22 21 2 306082
16 22 2 306082
17 22 2 306082
18 22 2 306082
19 22 2 306082
20 22 2 306082
21 22 2 306082
16 23 2 306082
17 23 2 306082
18 23 2 306082
19 23 2 306082
16 24 2 306082
16 16 3 ffffff
17 16 3 ffffff
18 16 3 ffffff
19 16 3 ffffff
20 16 3 ffffff
21 16 3 ffffff
22 16 3 ffffff
23 16 3 ffffff
24 16 3 ffffff
25 16 3 ffffff
16 17 3 ffffff
17 17 3 ffffff
18 17 3 ffffff
19 17 3 ffffff
20 17 3 ffffff
21 17 3 ffffff
22 17 3 ffffff
23 17 3 ffffff
24 17 3 ffffff
25 17 3 ffffff
16 18 3 ffffff
17 18 3 ffffff
18 18 3 ffffff
19 18 3 ffffff
20 18 3 ffffff
21 18 3 ffffff
22 18 3 ffffff
23 18 3 306082
24 18 3 306082
25 18 3 306082
16 19 3 306082
17 19 3 306082
18 19 3 306082
19 19 3 306082
20 19 3 306082
21 19 3 306082
22 19 3 306082
23 19 3 306082
24 19 3 306082
16 20 3 306082
17 20 3 306082
18 20 3 306082
19 20 3 306082
20 20 3 306082
21 20 3 306082
22 20 3 306082
23 20 3 306082
24 20 3 306082
16 21 3 306082
17 21 3 306082
18 21 3 306082
19 21 3 306082
20 21 3 306082
21 21 3 306082
22 21 3 306082
23 21 3 306082
16 22 3 306082
17 22 3 306082
18 22 3 306082
19 22 3 306082
20 22 3 306082
21 22 3 306082
22 22 3 306082
23 22 3 306082
16 23 3 306082
17 23 3 306082
18 23 3 306082
19 23 3 306082
20 23 3 306082
21 23 3 306082
22 23 3 306082
16 24 3 306082
17 24 3 306082
18 24 3 306082
19 24 3 306082
20 24 3 306082
16 25 3 306082
17 25 3 306082
18 25 3 306082
16 16 4 ffffff
17 16 4 ffffff
18 16 4 ffffff
19 16 4 ffffff
20 16 4 ffffff
21 16 4 ffffff
22 16 4 ffffff
23 16 4 ffffff
24 16 4 306082
25 16 4 306082
26 16 4 306082
16 17 4 ffffff
17 17 4 ffffff
18 17 4 ffffff
19 17 4 ffffff
20 17 4 ffffff
21 17 4 ffffff
22 17 4 ffffff
23 17 4 306082
24 17 4 306082
25 17 4 306082
26 17 4 306082
16 18 4 306082
17 18 4 306082
18 18 4 306082
19 18 4 306082
20 18 4 306082
21 18 4 306082
22 18 4 306082
23 18 4 306082
24 18 4 306082
25 18 4 306082
26 18 4 306082
16 19 4 306082
17 19 4 306082
18 19 4 306082
19 19 4 306082
20 19 4 306082
21 19 4 306082
22 19 4 306082
23 19 4 306082
